Workbook

Sheet BL
A1: DCM | B1: 2018 | C1: 2019 | D1: 2020 | E1: 2021 | F1: 2022 | G1: 2023 | H1: 2024 | I1: 2025
A2: ASSETS
A3: A. SHORT-TERM ASSETS | B3: 4318349 | C3: 4250037 | D3: 3978192 | E3: 7276292 | F3: 11624187 | G3: 13504495 | H3: 12920863 | I3: 14447095
A4: I. Cash and cash equivalents | B4: 285772 | C4: 471173 | D4: 509995 | E4: 427653 | F4: 2125625 | G4: 2284400 | H4: 1903248 | I4: 3590268
A5: 1. Cash | B5: 165772 | C5: 371173 | D5: 289995 | E5: 427653 | F5: 2125625 | G5: 2274400 | H5: 1903248 | I5: 3375268
A6: 2. Cash equivalents | B6: 120000 | C6: 100000 | D6: 220000 | G6: 10000 | I6: 215
A7: II. Short-term financial investments | B7: 2502000 | C7: 2002000 | D7: 2302000 | E7: 4362000 | F7: 6812000 | G7: 8242000 | H7: 7039051 | I7: 4082000
A8: 1. Available for sale securities
A9: 2. Provision for diminution in value of available for sale securities (*)
A10: 3. Held to maturity investments | B10: 2502000 | C10: 2002000 | D10: 2302000 | E10: 4362000 | F10: 6812000 | G10: 8242000 | H10: 7039051 | I10: 4082000
A11: III. Short-term receivables | B11: 452950 | C11: 401910 | D11: 217396 | E11: 187458 | F11: 188150 | G11: 365838 | H11: 528623 | I11: 1258875
A12: 1. Short-term trade accounts receivable | B12: 17544 | C12: 2926 | D12: 44754 | E12: 44654 | F12: 1405 | G12: 198512 | H12: 298905 | I12: 678419
A13: 2. Short-term prepayments to suppliers | B13: 86368 | C13: 55315 | D13: 15506 | E13: 86007 | F13: 86290 | G13: 54781 | H13: 225764 | I13: 432264
A14: 3. Short-term inter-company receivables
A15: 4. Construction contract progress receipts due from customers
A16: 5. Short-term loan receivables
A17: 6. Other short-term receivables | B17: 349039 | C17: 343753 | D17: 157278 | E17: 94288 | F17: 141989 | G17: 155143 | H17: 115443 | I17: 258724
A18: 7. Provision for short-term doubtful debts (*) | C18: -85 | D18: -141 | E18: -37490 | F18: -41534 | G18: -42598 | H18: -111488 | I18: -110532
A19: 8. Assets awaiting resolution
A20: IV. Inventories | B20: 982641 | C20: 1301123 | D20: 834135 | E20: 2204078 | F20: 2282528 | G20: 2160588 | H20: 2950301 | I20: 4808860
A21: 1. Inventories | B21: 982641 | C21: 1309837 | D21: 834430 | E21: 2204078 | F21: 2421843 | G21: 2192195 | H21: 2992365 | I21: 4891141
A22: 2. Provision for decline in value of inventories | C22: -8714 | D22: -296 | F22: -139315 | G22: -31607 | H22: -42064 | I22: -82281
A23: V. Other short-term assets | B23: 94985 | C23: 73831 | D23: 114666 | E23: 95103 | F23: 215884 | G23: 451669 | H23: 499639 | I23: 707092
A24: 1. Short-term prepayments | B24: 58791 | C24: 48533 | D24: 39703 | E24: 41799 | F24: 63632 | G24: 324690 | H24: 348206 | I24: 185701
A25: 2. Value added tax to be reclaimed | B25: 35648 | C25: 24729 | D25: 74461 | E25: 52802 | F25: 151749 | G25: 126477 | H25: 150931 | I25: 520889
A26: 3. Taxes and other receivables from state authorities | B26: 546 | C26: 569 | D26: 502 | E26: 502 | F26: 502 | G26: 502 | H26: 502 | I26: 502
A27: 4. Government bonds
A28: 5. Other short-term assets
A29: B. LONG-TERM ASSETS | B29: 6712237 | C29: 5922558 | D29: 4739289 | E29: 3795830 | F29: 2542674 | G29: 1733471 | H29: 2807985 | I29: 3196544
A30: I. Long-term receivables | B30: 3 | C30: 3 | D30: 3 | E30: 3 | H30: 512 | I30: 512
A31: 1. Long-term trade receivables
A32: 2. Long-term prepayments to suppliers
A33: 3. Capital at inter-company
A34: 4. Long-term inter-company receivables
A35: 5. Long-term loan receivables
A36: 6. Other long-term receivables | B36: 3 | C36: 3 | D36: 3 | E36: 3 | H36: 512 | I36: 512
A37: 7. Provision for long-term doubtful debts
A38: II. Fixed assets | B38: 6336415 | C38: 5187636 | D38: 3955429 | E38: 3405623 | F38: 2206853 | G38: 1600175 | H38: 1946194 | I38: 2175474
A39: 1. Tangible fixed assets | B39: 6297636 | C39: 5134488 | D39: 3899631 | E39: 3366688 | F39: 2159645 | G39: 1249768 | H39: 1571196 | I39: 1738283
A40: - Cost | B40: 14052806 | C40: 14202688 | D40: 14272461 | E40: 15104051 | F40: 15270938 | G40: 15430177 | H40: 16486332 | I40: 16958838
...

Sheet IS
A1: DCM | B1: 2018 | C1: 2019 | D1: 2020 | E1: 2021 | F1: 2022 | G1: 2023 | H1: 2024 | I1: 2025
A2: 1. Revenue | B2: 6827334 | C2: 7176575 | D2: 7716890 | E2: 10088157 | F2: 16380040 | G2: 12949489 | H2: 13942548 | I2: 17223063
A3: 2. Deduction from revenue | B3: 138005 | C3: 133609 | D3: 155615 | E3: 218394 | F3: 455513 | G3: 378947 | H3: 486963 | I3: 592133
A4: 3. Net revenue | B4: 6689329 | C4: 7042967 | D4: 7561275 | E4: 9869763 | F4: 15924527 | G4: 12570542 | H4: 13455585 | I4: 16630930
A5: 4. Cost of goods sold | B5: 5252270 | C5: 6083775 | D5: 6244427 | E5: 7088826 | F5: 10221097 | G5: 10538742 | H5: 10942101 | I5: 12582273
A6: 5. Gross profit | B6: 1437058 | C6: 959192 | D6: 1316848 | E6: 2780937 | F6: 5703429 | G6: 2031800 | H6: 2513484 | I6: 4048657
A7: 6. Financial income | B7: 176153 | C7: 127016 | D7: 128317 | E7: 167532 | F7: 301008 | G7: 577088 | H7: 381804 | I7: 394908
A8: 7. Financial expenses | B8: 260130 | C8: 102753 | D8: 63235 | E8: 45073 | F8: 60402 | G8: 27372 | H8: 76569 | I8: 97431
A9: Of which: Interest expenses | B9: 142053 | C9: 87173 | D9: 43301 | E9: 18580 | F9: 10275 | G9: 10156 | H9: 44381 | I9: 70405
A10: 8. Share of associates and joint ventures' result
A11: 9. Selling expenses | B11: 336115 | C11: 364059 | D11: 369000 | E11: 420401 | F11: 698295 | G11: 800631 | H11: 1014370 | I11: 1175972
A12: 10. General and administrative expenses | B12: 320103 | C12: 201319 | D12: 304407 | E12: 528492 | F12: 652594 | G12: 548557 | H12: 481047 | I12: 967951
A13: 11. Operating profit | B13: 696863 | C13: 418077 | D13: 708523 | E13: 1954503 | F13: 4593146 | G13: 1232327 | H13: 1323302 | I13: 2202212
A14: 12. Other income | B14: 14254 | C14: 48483 | D14: 10735 | E14: 4371 | F14: 15226 | G14: 24752 | H14: 199877 | I14: 7.04
A15: 13.Other expenses | B15: 4918 | C15: 3472 | D15: 2725 | E15: 2604 | F15: 12059 | G15: 2269 | H15: 1116 | I15: 1816
A16: 14. Other profit | B16: 9336 | C16: 45011 | D16: 8011 | E16: 1767 | F16: 3166 | G16: 22482 | H16: 198761 | I16: 5223
A17: Share of associates and joint ventures' result
A18: 15. Profit before tax | B18: 706199 | C18: 463088 | D18: 716534 | E18: 1956270 | F18: 4596313 | G18: 1254810 | H18: 1522063 | I18: 2207435
A19: 16. Current corporate income tax expenses | B19: 45721 | C19: 41018 | D19: 52562 | E19: 138029 | F19: 269999 | G19: 146469 | H19: 99848 | I19: 260385
A20: 17. Deferred income tax expenses (*) | B20: 1418 | C20: -5653 | D20: 1526 | E20: -7884 | F20: 5233 | G20: -1802 | H20: -5791 | I20: -14788
A21: 18. Net profit after tax | B21: 659059 | C21: 427724 | D21: 662446 | E21: 1826124 | F21: 4321081 | G21: 1110143 | H21: 1428007 | I21: 1961838
A22: Minority's interest | B22: 2914 | C22: 1548 | D22: 1400 | E22: 2665 | F22: 5127 | G22: 1250 | H22: 8349 | I22: 2025
A23: Profit after tax for shareholders of parent company | B23: 656145 | C23: 426175 | D23: 661046 | E23: 1823459 | F23: 4315953 | G23: 1108893 | H23: 1419658 | I23: 1959812
A24: 19. Earnings per share | B24: 1114 | C24: 595 | D24: 1017 | E24: 3073 | F24: 7701 | G24: 1797 | H24: 2394 | I24: 3203
A25: 20. Diluted earnings per share | E25: 3073

Sheet CF
A1: CASHFLOW INDIRECT | B1: 2018 | C1: 2019 | D1: 2020 | E1: 2021 | F1: 2022 | G1: 2023 | H1: 2024 | I1: 2025
A2: Cash and cash equivalents at end of the period | B2: 285772 | C2: 471173 | D2: 509995 | E2: 427653 | F2: 2125625 | G2: 2284400 | H2: 1903248 | I2: 3590268
A3: I. CASH FLOWS FROM OPERATING ACTIVITIES
A4: 1. Profit before tax | B4: 706199 | C4: 463088 | D4: 716534 | E4: 1956270 | F4: 4596313 | G4: 1254810 | H4: 1522063 | I4: 2207435
A5: 2. Adjustments for:
A6: Depreciation of fixed assets and properties investment | B6: 1303376 | C6: 1318841 | D6: 1318152 | E6: 1385811 | F6: 1398029 | G6: 1083381 | H6: 268081 | I6: 342065
A7: (Reversal of provisions)/provisions | C7: 8918 | D7: -8482 | E7: 37053 | F7: 822620 | G7: -212576 | H7: 9477 | I7: -576885
A8: Foreign exchange (gain)/loss from revaluation of monetary items denominated in foreign currencies | B8: 49850 | C8: -2435 | D8: -1535 | E8: -7009 | F8: 9327 | G8: -43610 | H8: 2.95 | I8: 2478
A9: Loss/(profit) from investment activities | B9: -158476 | C9: -117700 | D9: -111928 | E9: -130836 | F9: -265290 | G9: -518475 | H9: -451859 | I9: -288398
A10: Interest expense | B10: 142053 | C10: 87173 | D10: 43301 | E10: 18580 | F10: 10275 | G10: 10156 | H10: 44381 | I10: 70405
A11: Loss/(profits) from disposal of fixed asset
A12: Interest income and dividends | B12: 71306
A13: Allocation of goodwill
A14: Adjustments for | D14: 79425 | E14: 216728 | F14: 318817 | G14: 108886 | H14: 40508 | I14: 187993
A15: 3. Operating profit before changes in working capital | B15: 2114307 | C15: 1757884 | D15: 2035468 | E15: 3476598 | F15: 6890091 | G15: 1682571 | H15: 1435602 | I15: 1945094
A16: (Increase)/decrease in receivables | B16: -48477 | C16: 55144 | D16: 135340 | E16: 30361 | F16: -50565 | G16: -140256 | H16: -40518 | I16: -1139307
A17: (Increase)/decrease in inventories | B17: -611979 | C17: -327196 | D17: 475407 | E17: -1369647 | F17: -217765 | G17: 229648 | H17: -616691 | I17: -1903155
A18: Increase/(decrease) in payables (other than interest, corporate income tax) | B18: 411357 | C18: 93621 | D18: -702525 | E18: 988217 | F18: -413865 | G18: 875346 | H18: -233.41 | I18: 825659
A19: (Increase)/decrease in prepaid expenses | B19: -50958 | C19: 8943 | D19: 20815 | E19: -283791 | F19: -5626 | G19: -1716 | H19: -20966 | I19: 99861
A20: Changes in available for sale securities
A21: Interest paid | B21: -174064 | C21: -100442 | D21: -57260 | E21: -22321 | F21: -11564 | G21: -9755 | H21: -40667 | I21: -71328
A22: Corporate income tax paid | B22: -29470 | C22: -52401 | D22: -42054 | E22: -78860 | F22: -294531 | G22: -153898 | H22: -118.2 | I22: -222895
A23: Other receipts from operating activities | C23: 3
A24: Other payments for operating activities | B24: -81717 | C24: -64794 | D24: -84561 | E24: -171728 | F24: -164565 | G24: -168990 | H24: -287601 | I24: -309771
A25: Net cash flows from operating activities | B25: 1529000 | C25: 1370763 | D25: 1780630 | E25: 2568828 | F25: 5731610 | G25: 2312950 | H25: 77549 | I25: -775842
A26: II. CASH FLOWS FROM INVESTING ACTIVITIES
A27: 1. Payment for fixed assets, constructions and other long-term assets | B27: -341454 | C27: -414763 | D27: -272862 | E27: -156948 | F27: -146931 | G27: -544068 | H27: -791.15 | I27: -694635
A28: 2. Receipts from disposal of fixed assets and other long-term assets | F28: 3141 | H28: 4092 | I28: 1582
A29: 3. Loans, purchases of other entities' debt instruments | B29: -5572000 | C29: -3220000 | D29: -3290000 | E29: -6530000 | F29: -12260000 | G29: -13920000 | H29: -13442051 | I29: -11572000
A30: 4. Receipts from loan repayments, sale of other entities' debt instruments | B30: 5170000 | C30: 3720000 | D30: 2990000 | E30: 4470000 | F30: 9810000 | G30: 12490000 | H30: 14645000 | I30: 14529051
A31: 5. Payments for investment in other entities | H31: -598584 | I31: -745
A32: 6. Collections on investment in other entities
A33: 7. Dividends, interest and profit received | B33: 162437 | C33: 124405 | D33: 111386 | E33: 114722 | F33: 209034 | G33: 504959 | H33: 323803 | I33: 326.87
A34: 8. Increase/(Decrease) in term deposit
A35: 9. Purchases of minority shares of subsidiaries
A36: 10. Other receipts from investing activities
A37: 11. Other payments for investing activities
A38: Net cash flows from investing activities | B38: -581017 | C38: 209642 | D38: -461476 | E38: -2102226 | F38: -2384756 | G38: -1469109 | H38: 141.11 | I38: 2590122
A39: III. CASH FLOWS FROM FINANCING ACTIVITIES
A40: 1. Receipts from equity issue and owner's capital contribution
...

Sheet NWC
A1: NET WORKING CAPITAL
A2: Year | B2: 2018 | C2: 2019 | D2: 2020 | E2: 2021 | F2: 2022 | G2: 2023 | H2: 2024 | I2: 2025 | J2: 2026 | K2: 2027 | L2: 2028
A3: Accounts receivable - short term | B3: =BL!B11 -> 452950 | C3: =BL!C11 -> 401910 | D3: =BL!D11 -> 217396 | E3: =BL!E11 -> 187458 | F3: =BL!F11 -> 188150 | G3: =BL!G11 -> 365838 | H3: =BL!H11 -> 528623 | I3: =BL!I11 -> 1258875 | J3: =(J18*J20)/365 -> 698911.44 | K3: =(K18*K20)/365 -> 825663.46 | L3: =(L18*L20)/365 -> 975402.77
A4: Inventories | B4: =BL!B20 -> 982641 | C4: =BL!C20 -> 1301123 | D4: =BL!D20 -> 834135 | E4: =BL!E20 -> 2204078 | F4: =BL!F20 -> 2282528 | G4: =BL!G20 -> 2160588 | H4: =BL!H20 -> 2950301 | I4: =BL!I20 -> 4808860 | J4: =(J19*J21)/365 -> 3193659.9 | K4: =(K19*K21)/365 -> 3772850.3 | L4: =(L19*L21)/365 -> 4457080.6
A5: Other current assets | B5: =BL!B23 -> 94985 | C5: =BL!C23 -> 73831 | D5: =BL!D23 -> 114666 | E5: =BL!E23 -> 95103 | F5: =BL!F23 -> 215884 | G5: =BL!G23 -> 451669 | H5: =BL!H23 -> 499639 | I5: =BL!I23 -> 707092 | J5: =J18*J23 -> 324080.02 | K5: =K18*K23 -> 382853.98 | L5: =L18*L23 -> 452286.98
A6: Current assets | B6: =SUM(B3:B5) -> 1530576 | C6: =SUM(C3:C5) -> 1776864 | D6: =SUM(D3:D5) -> 1166197 | E6: =SUM(E3:E5) -> 2486639 | F6: =SUM(F3:F5) -> 2686562 | G6: =SUM(G3:G5) -> 2978095 | H6: =SUM(H3:H5) -> 3978563 | I6: =SUM(I3:I5) -> 6774827 | ... L6: =SUM(L3:L5) -> 5884770.4
A7: Accounts payable to suppliers | B7: =BL!B71 -> 760187 | C7: =BL!C71 -> 879302 | D7: =BL!D71 -> 709127 | E7: =BL!E71 -> 794797 | F7: =BL!F71 -> 1028476 | G7: =BL!G71 -> 1989283 | H7: =BL!H71 -> 1611511 | I7: =BL!I71 -> 1765886 | J7: =(J18*J22)/365 -> 2633787.3 | K7: =(K18*K22)/365 -> 3111441.4 | L7: =(L18*L22)/365 -> 3675721
A8: Payments to employees | B8: =BL!B74 -> 24338 | C8: =BL!C74 -> 94837 | D8: =BL!D74 -> 98041 | E8: =BL!E74 -> 187589 | F8: =BL!F74 -> 136581 | G8: =BL!G74 -> 150052 | H8: =BL!H74 -> 168883 | I8: =BL!I74 -> 329644 | J8: =J18*J24 -> 227873.16 | K8: =K18*K24 -> 269199.4 | L8: =L18*L24 -> 318020.42
A9: Bonus and welfare fund | B9: =BL!B82 -> 41586 | C9: =BL!C82 -> 104358 | D9: =BL!D82 -> 154922 | E9: =BL!E82 -> 195121 | F9: =BL!F82 -> 306565 | G9: =BL!G82 -> 335746 | H9: =BL!H82 -> 240509 | I9: =BL!I82 -> 289984 | J9: =J18*J25 -> 351199.68 | K9: =K18*K25 -> 414891.97 | L9: =L18*L25 -> 490135.26
A10: Advances from customers | B10: =BL!B72 -> 139371 | C10: =BL!C72 -> 45098 | D10: =BL!D72 -> 118183 | E10: =BL!E72 -> 285547 | F10: =BL!F72 -> 106451 | G10: =BL!G72 -> 23308 | H10: =BL!H72 -> 233212 | I10: =BL!I72 -> 697167 | J10: =J18*J26 -> 263069.21 | K10: =K18*K26 -> 310778.48 | L10: =L18*L26 -> 367140.13
A11: Other payables - short term | B11: =BL!B79 -> 231678 | C11: =BL!C79 -> 203311 | D11: =BL!D79 -> 127382 | E11: =BL!E79 -> 386498 | F11: =BL!F79 -> 304137 | G11: =BL!G79 -> 65902 | H11: =BL!H79 -> 64017 | I11: =BL!I79 -> 102443 | J11: =J18*J27 -> 471034.42 | K11: =K18*K27 -> 556459.5 | L11: =L18*L27 -> 657376.96
A12: Current liabilities | B12: =SUM(B7:B11) -> 1197160 | C12: =SUM(C7:C11) -> 1326906 | D12: =SUM(D7:D11) -> 1207655 | E12: =SUM(E7:E11) -> 1849552 | F12: =SUM(F7:F11) -> 1882210 | G12: =SUM(G7:G11) -> 2564291 | H12: =SUM(H7:H11) -> 2318132 | I12: =SUM(I7:I11) -> 3185124 | ... L12: =SUM(L7:L11) -> 5508393.7
A16: ASSUMPTIONS
A17: Year | B17: 2018 | C17: 2019 | D17: 2020 | E17: 2021 | F17: 2022 | G17: 2023 | H17: 2024 | I17: 2025 | J17: 2026 | K17: 2027 | L17: 2028
A18: Net revenue | B18: =IS!B4 -> 6689329 | C18: =IS!C4 -> 7042967 | D18: =IS!D4 -> 7561275 | E18: =IS!E4 -> 9869763 | F18: =IS!F4 -> 15924527 | G18: =IS!G4 -> 12570542 | H18: =IS!H4 -> 13455585 | I18: =IS!I4 -> 16630930 | J18: =Data!J3 -> 19647055 | K18: =Data!K3 -> 23210172 | L18: =Data!L3 -> 27419484
A19: Cost of goods sold | B19: =IS!B5 -> 5252270 | C19: =IS!C5 -> 6083775 | D19: =IS!D5 -> 6244427 | E19: =IS!E5 -> 7088826 | F19: =IS!F5 -> 10221097 | G19: =IS!G5 -> 10538742 | H19: =IS!H5 -> 10942101 | I19: =IS!I5 -> 12582273 | J19: =Data!J4 -> 15043272 | K19: =Data!K4 -> 17771465 | L19: =Data!L4 -> 20994433
A20: Days sale outstanding | B20: =(B3/B18)*365 -> 24.714998 | C20: =(C3/C18)*365 -> 20.828885 | D20: =(D3/D18)*365 -> 10.494201 | E20: =(E3/E18)*365 -> 6.9325039 | F20: =(F3/F18)*365 -> 4.3125143 | G20: =(G3/G18)*365 -> 10.622523 | H20: =AVERAGE(B20:G20) -> 12.984271 | I20: =H20 -> 12.984271 | J20: =I20 -> 12.984271 | K20: =J20 -> 12.984271 | L20: =K20 -> 12.984271
A21: Days inventory outstanding | B21: =(B4/B19)*365 -> 68.28742 | C21: =(C4/C19)*365 -> 78.061713 | D21: =(D4/D19)*365 -> 48.75696 | E21: =(E4/E19)*365 -> 113.48684 | F21: =(F4/F19)*365 -> 81.510108 | G21: =(G4/G19)*365 -> 74.830053 | H21: =AVERAGE(B21:G21) -> 77.488849 | I21: =H21 -> 77.488849 | J21: =I21 -> 77.488849 | K21: =J21 -> 77.488849 | L21: =K21 -> 77.488849
A22: Days payable outstanding | B22: =(B7/B19)*365 -> 52.828254 | C22: =(C7/C19)*365 -> 52.75429 | D22: =(D7/D19)*365 -> 41.449977 | E22: =(E7/E19)*365 -> 40.923688 | F22: =(F7/F19)*365 -> 36.727343 | G22: =(G7/G19)*365 -> 68.897056 | H22: =AVERAGE(B22:G22) -> 48.930101 | I22: =H22 -> 48.930101 | J22: =I22 -> 48.930101 | K22: =J22 -> 48.930101 | L22: =K22 -> 48.930101
A23: (Other current assets/net revenue)% | B23: =B5/B18 -> 0.014199481 | C23: =C5/C18 -> 0.01048294 | D23: =D5/D18 -> 0.015164903 | E23: =E5/E18 -> 0.0096357937 | F23: =F5/F18 -> 0.013556698 | G23: =G5/G18 -> 0.03593075 | H23: =AVERAGE(B23:G23) -> 0.016495094 | I23: =H23 -> 0.016495094 | J23: =I23 -> 0.016495094 | K23: =J23 -> 0.016495094 | L23: =K23 -> 0.016495094
A24: (Payments to employees/net revenue)% | B24: =B8/B18 -> 0.003638332 | C24: =C8/C18 -> 0.01346549 | D24: =D8/D18 -> 0.012966199 | E24: =E8/E18 -> 0.019006434 | F24: =F8/F18 -> 0.0085767697 | G24: =G8/G18 -> 0.011936796 | H24: =AVERAGE(B24:G24) -> 0.011598337 | I24: =H24 -> 0.011598337 | J24: =I24 -> 0.011598337 | K24: =J24 -> 0.011598337 | L24: =K24 -> 0.011598337
A25: (Bonus and welfare fund/net revenue)% | B25: =B9/B18 -> 0.006216767 | C25: =C9/C18 -> 0.014817335 | D25: =D9/D18 -> 0.020488873 | E25: =E9/E18 -> 0.019769573 | F25: =F9/F18 -> 0.019251121 | G25: =G9/G18 -> 0.026708952 | H25: =AVERAGE(B25:G25) -> 0.017875437 | I25: =H25 -> 0.017875437 | J25: =I25 -> 0.017875437 | K25: =J25 -> 0.017875437 | L25: =K25 -> 0.017875437
A26: (Advances from customers/net revenue)% | B26: =B10/B18 -> 0.020834825 | C26: =C10/C18 -> 0.0064032673 | D26: =D10/D18 -> 0.015630036 | E26: =E10/E18 -> 0.028931495 | F26: =F10/F18 -> 0.0066847197 | G26: =G10/G18 -> 0.0018541762 | H26: =AVERAGE(B26:G26) -> 0.013389753 | I26: =H26 -> 0.013389753 | J26: =I26 -> 0.013389753 | K26: =J26 -> 0.013389753 | L26: =K26 -> 0.013389753
A27: (Other payables - short term/net revenue)% | B27: =B11/B18 -> 0.034633967 | C27: =C11/C18 -> 0.028867237 | D27: =D11/D18 -> 0.01684663 | E27: =E11/E18 -> 0.039159806 | F27: =F11/F18 -> 0.019098652 | G27: =G11/G18 -> 0.0052425743 | H27: =AVERAGE(B27:G27) -> 0.023974811 | I27: =H27 -> 0.023974811 | J27: =I27 -> 0.023974811 | K27: =J27 -> 0.023974811 | L27: =K27 -> 0.023974811

Sheet Data
A1: FCF(mm)
A2: Year | B2: 2018 | C2: 2019 | D2: 2020 | E2: 2021 | F2: 2022 | G2: 2023 | H2: 2024 | I2: 2025 | J2: 2026 | K2: 2027 | L2: 2028 | M2: 2029 | N2: 2030
A3: Net revenue | B3: =IS!B4 -> 6689329 | C3: =IS!C4 -> 7042967 | D3: =IS!D4 -> 7561275 | E3: =IS!E4 -> 9869763 | F3: =IS!F4 -> 15924527 | G3: =IS!G4 -> 12570542 | H3: =IS!H4 -> 13455585 | I3: =IS!I4 -> 16630930 | J3: =I3*(1+J27) -> 19647055 | K3: =J3*(1+K27) -> 23210172 | L3: =K3*(1+L27) -> 27419484 | M3: =L3*(1+M27) -> 32392182 | N3: =M3*(1+N27) -> 38266709
A4: COGS | B4: =IS!B5 -> 5252270 | C4: =IS!C5 -> 6083775 | D4: =IS!D5 -> 6244427 | E4: =IS!E5 -> 7088826 | F4: =IS!F5 -> 10221097 | G4: =IS!G5 -> 10538742 | H4: =IS!H5 -> 10942101 | I4: =IS!I5 -> 12582273 | J4: =J3*J28 -> 15043272 | K4: =K3*K28 -> 17771465 | L4: =L3*L28 -> 20994433 | M4: =M3*M28 -> 24801906 | N4: =N3*N28 -> 29299889
A5: Gross profit | B5: =B3-B4 -> 1437059 | C5: =C3-C4 -> 959192 | D5: =D3-D4 -> 1316848 | E5: =E3-E4 -> 2780937 | F5: =F3-F4 -> 5703430 | G5: =G3-G4 -> 2031800 | H5: =H3-H4 -> 2513484 | I5: =I3-I4 -> 4048657 | ... N5: =N3-N4 -> 8966819.9
A6: Selling, general and administrative expenses | B6: =IS!B11+IS!B12 -> 656218 | C6: =IS!C11+IS!C12 -> 565378 | D6: =IS!D11+IS!D12 -> 673407 | E6: =IS!E11+IS!E12 -> 948893 | F6: =IS!F11+IS!F12 -> 1350889 | G6: =IS!G11+IS!G12 -> 1349188 | H6: =IS!H11+IS!H12 -> 1495417 | I6: =IS!I11+IS!I12 -> 2143923 | J6: =J3*J29 -> 2021716.4 | K6: =K3*K29 -> 2388367.4 | L6: =L3*L29 -> 2821513 | M6: =M3*M29 -> 3333212.3 | N6: =N3*N29 -> 3937711.5
A7: Total operating expenses | B7: =B6 -> 656218 | C7: =C6 -> 565378 | D7: =D6 -> 673407 | E7: =E6 -> 948893 | F7: =F6 -> 1350889 | G7: =G6 -> 1349188 | H7: =H6 -> 1495417 | I7: =I6 -> 2143923 | ... N7: =N6 -> 3937711.5
A8: EBITDA | B8: =B5-B7 -> 780841 | C8: =C5-C7 -> 393814 | D8: =D5-D7 -> 643441 | E8: =E5-E6 -> 1832044 | F8: =F5-F6 -> 4352541 | G8: =G5-G6 -> 682612 | H8: =H5-H6 -> 1018067 | I8: =I5-I6 -> 1904734 | J8: =J5-J6 -> 2582066 | K8: =K5-K6 -> 3050340 | L8: =L5-L6 -> 3603538.5 | ... N8: =N5-N6 -> 5029108.5
A9: Depreciation & amortization | B9: =-7755170+6461600-67111+53815 -> -1306866 | C9: =BL!C41-BL!B41+BL!C44-BL!B44+BL!C47-BL!B47 -> -1322226 | D9: =BL!D41-BL!C41+BL!D44-BL!C44+BL!D47-BL!C47 -> -1319237 | E9: =BL!E41-BL!D41+BL!E44-BL!D44+BL!E47-BL!D47 -> -1387785 | F9: =BL!F41-BL!E41+BL!F44-BL!E44+BL!F47-BL!E47 -> -1391022 | G9: =BL!G41-BL!F41+BL!G44-BL!F44+BL!G47-BL!F47 -> -1087768 | H9: =BL!H41-BL!G41+BL!H44-BL!G44+BL!H47-BL!G47 -> -759771 | I9: =BL!I41-BL!H41+BL!I44-BL!H44+BL!I47-BL!H47 -> -344644 | J9: =Capex!J4 -> -828464.03 | K9: =Capex!K4 -> -756908.54 | L9: =Capex!L4 -> -691533.39 | M9: =Capex!M4 -> -631804.77 | N9: =Capex!N4 -> -577234.99
A10: Operating profit (EBIT) | B10: =B8+B9 -> -526025 | C10: =C8+C9 -> -928412 | D10: =D8+D9 -> -675796 | E10: =E8-E9 -> 3219829 | F10: =F8-F9 -> 5743563 | G10: =G8-G9 -> 1770380 | H10: =H8-H9 -> 1777838 | I10: =I8-I9 -> 2249378 | J10: =J8-J9 -> 3410530 | K10: =K8-K9 -> 3807248.6 | L10: =L8-L9 -> 4295071.9 | ... N10: =N8-N9 -> 5606343.4
A11: Operating taxes | B11: =IS!B19+IS!B20 -> 47139 | C11: =IS!C19+IS!C20 -> 35365 | D11: =IS!D19+IS!D20 -> 54088 | E11: =IS!E19+IS!E20 -> 130145 | F11: =IS!F19+IS!F20 -> 275232 | G11: =IS!G19+IS!G20 -> 144667 | H11: =IS!H19+IS!H20 -> 94057 | I11: =IS!I19+IS!I20 -> 245597 | J11: =J8*J30 -> 108493.61 | K11: =K8*K30 -> 128169.62 | L11: =L8*L30 -> 151413.99 | M11: =M8*M30 -> 178873.87 | N11: =N8*N30 -> 211313.79
A12: Net operating profit after taxes | B12: =B10-B11 -> -573164 | C12: =C10-C11 -> -963777 | D12: =D10-D11 -> -729884 | E12: =E10-E11 -> 3089684 | F12: =F10-F11 -> 5468331 | G12: =G10-G11 -> 1625713 | H12: =H10-H11 -> 1683781 | I12: =I10-I11 -> 2003781 | ... N12: =N10-N11 -> 5395029.7
A13: (+) Depreciation & amortization | B13: =-B9 -> 1306866 | C13: =-C9 -> 1322226 | D13: =-D9 -> 1319237 | E13: =-E9 -> 1387785 | F13: =-F9 -> 1391022 | G13: =-G9 -> 1087768 | H13: =-H9 -> 759771 | I13: =-I9 -> 344644 | ... N13: =-N9 -> 577234.99
A14: (-) Capital expenditures | B14: =-Capex!B5 -> 2471995 | C14: =-Capex!C5 -> 2471005 | D14: =-Capex!D5 -> 2551444 | E14: =-Capex!E5 -> 1937591 | F14: =-Capex!F5 -> 2589792 | G14: =-Capex!H5 -> 413752 | H14: =-Capex!H5 -> 413752 | I14: =-Capex!I5 -> 115364 | J14: =-Capex!J5 -> 1016362.5 | K14: =-Capex!K5 -> 928577.97 | L14: =-Capex!L5 -> 848375.51 | M14: =-Capex!M5 -> 775100.24 | N14: =-Capex!N5 -> 708153.84
A15: (-) Change in NWC | B15: =(B16-((400479+370663+71383)-(437540+53669+83530+41228+221138))) -> 327996 | C15: =(C16-B16) -> 116542 | D15: =(D16-C16) -> -491416 | E15: =(E16-D16) -> 678545 | F15: =(F16-E16) -> 167265 | G15: =(G16-F16) -> -390548 | H15: =(H16-G16) -> 1246627 | I15: =(I16-H16) -> 1929272 | J15: =(J16-I16) -> -3320015.5 | ... N15: =(N16-M16) -> 0
A16: NWC | B16: =B17-B18 -> 333416 | C16: =C17-C18 -> 449958 | D16: =D17-D18 -> -41458 | E16: =E17-E18 -> 637087 | F16: =F17-F18 -> 804352 | G16: =G17-G18 -> 413804 | H16: =H17-H18 -> 1660431 | I16: =I17-I18 -> 3589703 | ... N16: =N17-N18 -> 0
A17: Current asset | B17: =NWC!B6 -> 1530576 | C17: =NWC!C6 -> 1776864 | D17: =NWC!D6 -> 1166197 | E17: =NWC!E6 -> 2486639 | F17: =NWC!F6 -> 2686562 | G17: =NWC!G6 -> 2978095 | H17: =NWC!H6 -> 3978563 | I17: =NWC!I6 -> 6774827 | ... N17: =NWC!N6 -> 0
A18: Current liabilities | B18: =NWC!B12 -> 1197160 | C18: =NWC!C12 -> 1326906 | D18: =NWC!D12 -> 1207655 | E18: =NWC!E12 -> 1849552 | F18: =NWC!F12 -> 1882210 | G18: =NWC!G12 -> 2564291 | H18: =NWC!H12 -> 2318132 | I18: =NWC!I12 -> 3185124 | ... N18: =NWC!N12 -> 0
A19: FCFF | B19: =B12+B13-B14-B15 -> -2066289 | C19: =C12+C13-C14-C15 -> -2229098 | D19: =D12+D13-D14-D15 -> -1470675 | E19: =E12+E13-E14-E15 -> 1861333 | F19: =F12+F13-F14-F15 -> 4102296 | G19: =G12+G13-G14-G15 -> 2690277 | H19: =H12+H13-H14-H15 -> 783173 | I19: =I12+I13-I14-I15 -> 303789 | ... N19: =N12+N13-N14-N15 -> 5264110.8 | P19: FCFF = NI + depre. - Capex - change WC
A20: Interest expenses | B20: =IS!B9 -> 142053 | C20: =IS!C9 -> 87173 | D20: =IS!D9 -> 43301 | E20: =IS!E9 -> 18580 | F20: =IS!F9 -> 10275 | G20: =IS!G9 -> 10156 | H20: =IS!H9 -> 44381 | I20: =IS!I9 -> 70405 | J20: =J3*J31 -> 64802.528 | K20: =K3*K31 -> 76554.878 | L20: =L3*L31 -> 90438.59 | M20: =M3*M31 -> 106840.2 | N20: =N3*N31 -> 126216.35
A21: FCFE | B21: =B19-B20 -> -2208342 | C21: =C19-C20 -> -2316271 | D21: =D19-D20 -> -1513976 | E21: =E19-E20 -> 1842753 | F21: =F19-F20 -> 4092021 | G21: =G19-G20 -> 2680121 | H21: =H19-H20 -> 738792 | I21: =I19-I20 -> 233384 | ... N21: =N19-N20 -> 5137894.5
A25: ASSUMPTIONS
A26: Year | B26: 2018 | C26: 2019 | D26: 2020 | E26: 2021 | F26: 2022 | G26: 2023 | H26: 2024 | I26: 2025 | J26: 2026 | K26: 2027 | L26: 2028 | M26: 2029 | N26: 2030
A27: Net revenue growth | B27: =(B3-5832973)/5832973 -> 0.14681295 | C27: =(C3-B3)/B3 -> 0.05286599 | D27: =(D3-C3)/C3 -> 0.07359228 | E27: =(E3-D3)/D3 -> 0.30530407 | F27: =(F3-E3)/E3 -> 0.613466 | G27: =(G3-F3)/F3 -> -0.21061756 | H27: =(H3-G3)/G3 -> 0.070406113 | I27: =(I3-H3)/H3 -> 0.23598714 | J27: =AVERAGE(D27:I27) -> 0.18135634 | K27: =J27 -> 0.18135634 | L27: =K27 -> 0.18135634 | M27: =L27 -> 0.18135634 | N27: =M27 -> 0.18135634
A28: COGS % of net revenue | B28: =B4/B3 -> 0.78517143 | C28: =C4/C3 -> 0.86380853 | D28: =D4/D3 -> 0.82584313 | E28: =E4/E3 -> 0.7182367 | F28: =F4/F3 -> 0.64184619 | G28: =G4/G3 -> 0.83836815 | H28: =H4/H3 -> 0.81320143 | I28: =I4/I3 -> 0.75655859 | J28: =AVERAGE(D28:I28) -> 0.7656757 | K28: =J28 -> 0.7656757 | L28: =K28 -> 0.7656757 | M28: =L28 -> 0.7656757 | N28: =M28 -> 0.7656757
A29: SG&A % of net revenue | B29: =B6/B3 -> 0.098099226 | C29: =C6/C3 -> 0.080275543 | D29: =D6/D3 -> 0.08905998 | E29: =E6/E3 -> 0.096141417 | F29: =F6/F3 -> 0.084830714 | G29: =G6/G3 -> 0.10732934 | H29: =H6/H3 -> 0.11113727 | I29: =I6/I3 -> 0.12891179 | J29: =AVERAGE(D29:I29) -> 0.10290175 | K29: =J29 -> 0.10290175 | L29: =K29 -> 0.10290175 | M29: =L29 -> 0.10290175 | N29: =M29 -> 0.10290175
A30: Taxes % of EBIT | B30: =B11/B10 -> -0.089613612 | C30: =C11/C10 -> -0.038091925 | D30: =D11/D10 -> -0.080035987 | E30: =E11/E10 -> 0.040419848 | F30: =F11/F10 -> 0.04792008 | G30: =G11/G10 -> 0.081715225 | H30: =H11/H10 -> 0.05290527 | I30: =I11/I10 -> 0.10918441 | J30: =AVERAGE(D30:I30) -> 0.04201814 | K30: =J30 -> 0.04201814 | L30: =K30 -> 0.04201814 | M30: =L30 -> 0.04201814 | N30: =M30 -> 0.04201814
A31: Interest expenses % of net revenue | B31: =B20/B3 -> 0.021235762 | C31: =C20/C3 -> 0.012377312 | D31: =D20/D3 -> 0.0057266797 | E31: =E20/E3 -> 0.0018825173 | F31: =F20/F3 -> 0.0006452311 | G31: =G20/G3 -> 0.00080792061 | H31: =H20/H3 -> 0.003298333 | I31: =H20/H3 -> 0.003298333 | J31: =+I31 -> 0.003298333 | K31: =J31 -> 0.003298333 | L31: =K31 -> 0.003298333 | M31: =L31 -> 0.003298333 | N31: =M31 -> 0.003298333 | P31: DCM đang net cash position, đi vay với mục đích bổ sung vốn lưu động, dư nợ vay rất ít, chi phí lãi vay ko đáng kể.

Sheet Capex
A1: FIXED ASSETS
A2: Year | B2: 2018 | C2: 2019 | D2: 2020 | E2: 2021 | F2: 2022 | G2: 2023 | H2: 2024 | I2: 2025 | J2: 2026 | K2: 2027 | L2: 2028 | M2: 2029 | N2: 2030
A3: Beginning PP&E | B3: 7501544 | C3: =BL!B38 -> 6336415 | D3: =BL!C38 -> 5187636 | E3: =BL!D38 -> 3955429 | F3: =BL!E38 -> 3405623 | G3: =BL!F38 -> 2206853 | H3: =BL!G38 -> 1600175 | I3: =BL!H38 -> 1946194 | J3: =I6 -> 2175474 | K3: =J6 -> 1987575.5 | L3: =K6 -> 1815906.1 | M3: =L6 -> 1659064 | N3: =M6 -> 1515768.5
A4: D&A | B4: =Data!B9 -> -1306866 | C4: =Data!C9 -> -1322226 | D4: =Data!D9 -> -1319237 | E4: =Data!E9 -> -1387785 | F4: =Data!F9 -> -1391022 | G4: =Data!G9 -> -1087768 | H4: =Data!H9 -> -759771 | I4: =Data!I9 -> -344644 | J4: =J3*J12 -> -828464.03 | K4: =K3*K12 -> -756908.54 | L4: =L3*L12 -> -691533.39 | M4: =M3*M12 -> -631804.77 | N4: =N3*N12 -> -577234.99
A5: Capital expenditures | B5: =B6-B3+B4 -> -2471995 | C5: =C6-C3+C4 -> -2471005 | D5: =D6-D3+D4 -> -2551444 | E5: =E6-E3+E4 -> -1937591 | F5: =F6-F3+F4 -> -2589792 | G5: =G6-G3+G4 -> -1694446 | H5: =H6-H3+H4 -> -413752 | I5: =I6-I3+I4 -> -115364 | J5: =J3*J13 -> -1016362.5 | K5: =K3*K13 -> -928577.97 | L5: =L3*L13 -> -848375.51 | M5: =M3*M13 -> -775100.24 | N5: =N3*N13 -> -708153.84
A6: Ending PP&E | B6: =BL!B38 -> 6336415 | C6: =BL!C38 -> 5187636 | D6: =BL!D38 -> 3955429 | E6: =BL!E38 -> 3405623 | F6: =BL!F38 -> 2206853 | G6: =BL!G38 -> 1600175 | H6: =BL!H38 -> 1946194 | I6: =BL!I38 -> 2175474 | J6: =J3+J5-J4 -> 1987575.5 | K6: =K3+K5-K4 -> 1815906.1 | L6: =L3+L5-L4 -> 1659064 | M6: =M3+M5-M4 -> 1515768.5 | N6: =N3+N5-N4 -> 1384849.7
A10: ASSUMPTIONS
A11: Year | B11: 2018 | C11: 2019 | D11: 2020 | E11: 2021 | F11: 2022 | G11: 2023 | H11: 2024 | I11: 2025 | J11: 2026 | K11: 2027 | L11: 2028 | M11: 2029 | N11: 2030
A12: D&A as % of beginning PP&E | B12: =B4/B3 -> -0.17421294 | C12: =C4/C3 -> -0.20867099 | D12: =D4/D3 -> -0.25430408 | E12: =E4/E3 -> -0.35085575 | F12: =F4/F3 -> -0.40844862 | G12: =G4/G3 -> -0.4929046 | H12: =H4/H3 -> -0.47480494 | I12: =I4/I3 -> -0.17708615 | J12: =AVERAGE(E12:I12) -> -0.38082001 | K12: =J12 -> -0.38082001 | L12: =K12 -> -0.38082001 | M12: =L12 -> -0.38082001 | N12: =M12 -> -0.38082001
A13: CapEx as % of beginning PP&E | B13: =B5/B3 -> -0.32953149 | C13: =C5/C3 -> -0.38996893 | D13: =D5/D3 -> -0.49183173 | E13: =E5/E3 -> -0.48985609 | F13: =F5/F3 -> -0.76044589 | G13: =G5/G3 -> -0.767811 | H13: =H5/H3 -> -0.25856672 | I13: =I5/I3 -> -0.059276722 | J13: =AVERAGE(E13:I13) -> -0.46719128 | K13: =J13 -> -0.46719128 | L13: =K13 -> -0.46719128 | M13: =L13 -> -0.46719128 | N13: =M13 -> -0.46719128

Sheet WACC
A1: Rd | B1: 0.0314
A2: Tax | B2: 0.2
A3: Kd | B3: =B1*(1-B2) -> 0.02512
A4: Wd | B4: 0.33797162 | D4: DCM đang net cash position, ko có nợ
A5: Rf | B5: 0.02759
A6: Rm- Rf | B6: 0.09
A7: Beta | B7: 0.989
A8: Ke | B8: =B5+B7*B6 -> 0.1166
A9: We | B9: =1-B4 -> 0.66202838
A10: WACC | B10: =B9*B8+B4*B3 -> 0.085682356

Sheet FCFF
A1: FCFF
A2: Year | B2: 2018 | C2: 2019 | D2: 2020 | E2: 2021 | F2: 2022 | G2: 2023 | H2: 2024 | I2: 2025 | J2: 2026 | K2: 2027 | L2: 2028
A3: FCFF | B3: =Data!B19 -> -2066289 | C3: =Data!C19 -> -2229098 | D3: =Data!D19 -> -1470675 | E3: =Data!E19 -> 1861333 | F3: =Data!F19 -> 4102296 | G3: =Data!G19 -> 2690277 | H3: =Data!H19 -> 783173 | I3: =Data!I19 -> 303789 | ... L3: =Data!L19 -> 3929036.2
A4: Project years | H4: 1 | I4: 2 | J4: 3 | K4: 4 | L4: 5
A5: PV(FCFF) | H5: =H3/(1+$B$12)^H4 -> 721364.77 | I5: =I3/(1+$B$12)^I4 -> 257730.9 | J5: =J3/(1+$B$12)^J4 -> 5027858.8 | K5: =K3/(1+$B$12)^K4 -> 2489296.7 | L5: =L3/(1+$B$12)^L4 -> 2604786.5
A9: CALCULATION
A10: Sum PV of FCFF | B10: =SUM(H5:L5) -> 11101038
A11: Terminal growth rate | B11: 0.01
A12: WACC | B12: =WACC!B10 -> 0.085682356
A13: Terminal value (Pt) | B13: =(L3*(1+B11)/(B12-B11)) -> 52433972
A14: PV(Terminal value) | B14: =B13/(1+B12)^L4 -> 34761528
A15: Firm value | B15: =B10+B14 -> 45862566
A16: Debt | B16: =+BL!G80+BL!G93-BL!G4-BL!G7 -> -9677630 | D16: Net debts = tổng nợ vay ngân hàng - tiền
A17: Number of share outstanding | B17: 529400000
A18: P0 | B18: =(B15-B16)*10^6/B17 -> 104911.59

Sheet FCFE
A1: FCFE
A2: Year | B2: 2018 | C2: 2019 | D2: 2020 | E2: 2021 | F2: 2022 | G2: 2023 | H2: 2024 | I2: 2025 | J2: 2026 | K2: 2027 | L2: 2028
A3: FCFE | B3: =Data!B21 -> -2208342 | C3: =Data!C21 -> -2316271 | D3: =Data!D21 -> -1513976 | E3: =Data!E21 -> 1842753 | F3: =Data!F21 -> 4092021 | G3: =Data!G21 -> 2680121 | H3: =Data!H21 -> 738792 | I3: =Data!I21 -> 233384 | ... L3: =Data!L21 -> 3838597.6
A4: Project years | H4: 1 | I4: 2 | J4: 3 | K4: 4 | L4: 5
A5: PV(FCFE) | H5: =H3/(1+$B$12)^H4 -> 680486.33 | I5: =I3/(1+$B$12)^I4 -> 198000.15 | J5: =J3/(1+$B$12)^J4 -> 4977220 | K5: =K3/(1+$B$12)^K4 -> 2434195.4 | L5: =L3/(1+$B$12)^L4 -> 2544829.5
A9: CALCULATION
A10: Sum PV of FCFE | B10: =SUM(H5:L5) -> 10834731
A11: Terminal growth rate | B11: =FCFF!B11 -> 0.01
A12: Ke | B12: =FCFF!B12 -> 0.085682356
A13: Terminal value (Pt) | B13: =L3*(1+B11)/(B12-B11) -> 51227047
A14: PV(Terminal value) | B14: =B13/(1+B12)^L4 -> 33961387
A15: Market value of E | B15: =B10+B14 -> 44796118
A16: Number of share outstanding | B16: =FCFF!B17 -> 529400000
A17: P0 | B17: =B15*10^6/B16 -> 84616.77

Sheet PE
A1: P/E
B2: 2018 | C2: 2019 | D2: 2020 | E2: 2021 | F2: 2022 | G2: 2023 | H2: TB
A3: Number of share outstanding | B3: =FCFF!B17 -> 529400000 | C3: =B3 -> 529400000 | D3: =B3 -> 529400000 | E3: =B3 -> 529400000 | F3: =B3 -> 529400000 | G3: =C3 -> 529400000
A4: Net profit after tax | B4: =IS!B21 -> 659059 | C4: =IS!C21 -> 427724 | D4: =IS!D21 -> 662446 | E4: =IS!E21 -> 1826124 | F4: =IS!F21 -> 4321081 | G4: =IS!G21 -> 1110143
A5: EPS | B5: =B4*10^6/B3 -> 1244.9169 | C5: =C4*10^6/C3 -> 807.94107 | D5: =D4*10^6/D3 -> 1251.3147 | E5: =E4*10^6/E3 -> 3449.422 | F5: =F4*10^6/F3 -> 8162.2233 | G5: =G4*10^6/G3 -> 2096.9834 | H5: =AVERAGE(B5:G5) -> 2835.4669
A6: P/E ngành | B6: 13.49
A7: Price | B7: =B6*H5 -> 38250.448

Sheet PB
A1: P/B
B2: 2018 | C2: 2019 | D2: 2020 | E2: 2021 | F2: 2022 | G2: 2023
A3: Number of share outstanding | B3: =FCFF!B17 -> 529400000 | C3: =B3 -> 529400000 | D3: =B3 -> 529400000 | E3: =B3 -> 529400000 | F3: =B3 -> 529400000 | G3: =C3 -> 529400000
A4: Book value of asset | B4: =BL!B67 -> 11030586 | C4: =BL!C67 -> 10172595 | D4: =BL!D67 -> 8717481 | E4: =BL!E67 -> 11072121 | F4: =BL!F67 -> 14166861 | G4: =BL!G67 -> 15237966
A5: Book value of debt | B5: =BL!B69 -> 4761714 | C5: =BL!C69 -> 4066268 | D5: =BL!D69 -> 2391033 | E5: =BL!E69 -> 3594024 | F5: =BL!F69 -> 3561412 | G5: =BL!G69 -> 5274583
A6: Book value of equity | B6: =B4-B5 -> 6268872 | C6: =C4-C5 -> 6106327 | D6: =D4-D5 -> 6326448 | E6: =E4-E5 -> 7478097 | F6: =F4-F5 -> 10605449 | G6: =G4-G5 -> 9963383
A7: BPS | B7: =B6*10^6/B3 -> 11841.466 | C7: =C6*10^6/C3 -> 11534.43 | D7: =D6*10^6/D3 -> 11950.223 | E7: =E6*10^6/E3 -> 14125.608 | F7: =F6*10^6/F3 -> 20032.96 | G7: =G6*10^6/G3 -> 18820.142
A8: P/B ngành (giả định) | B8: 2.37
A9: Price | B9: =+B8*G7 -> 44603.736

Sheet EV.EBITDA
A1: EV/EBITDA
B2: 2018 | C2: 2019 | D2: 2020 | E2: 2021 | F2: 2022 | G2: 2023 | H2: TB Ngành
A3: Number of share outstanding | B3: =FCFF!B17 -> 529400000 | C3: =B3 -> 529400000 | D3: =B3 -> 529400000 | E3: =B3 -> 529400000 | F3: =B3 -> 529400000 | G3: =B3 -> 529400000
A4: Price on 1/12 | B4: 8.3 | C4: 5.85 | D4: 13.2 | E4: 34.6 | F4: 26.5 | G4: 32.35
A5: Market capitalization | B5: =B3*B4*10^3 -> 4394020000000 | C5: =C3*C4*10^3 -> 3096990000000 | D5: =D3*D4*10^3 -> 6988080000000 | E5: =E3*E4*10^3 -> 18317240000000 | F5: =F4*10^3*F3 -> 14029100000000 | G5: =G4*G3*10^3 -> 17126090000000
A6: Cash and cash equivalents | B6: =BL!B4+BL!B7 -> 2787772 | C6: =BL!C4+BL!C7 -> 2473173 | D6: =BL!D4+BL!D7 -> 2811995 | E6: =BL!E4+BL!E7 -> 4789653 | F6: =BL!F4+BL!F7 -> 8937625 | I6: Mục này bao gồm tiền và tiền gửi ngân hàng
A7: Loan debt | B7: =BL!B80+BL!B93 -> 2704215 | C7: =BL!C80+BL!C93 -> 1784844 | D7: =BL!D80+BL!D93 -> 822469 | E7: =BL!E80+BL!E93 -> 691839 | F7: =BL!F80+BL!F93 -> 3607
A8: EV | B8: =B5+B7-B6 -> 4394019916443 | C8: =C5+C7-C6 -> 3096989311671 | D8: =D5+D7-D6 -> 6988078010474 | E8: =E5+E7-E6 -> 18317235902186 | F8: =F5+F7-F6 -> 14029091065982
A9: EBITDA | B9: =IS!B18+CF!B9+CF!B6 -> 1851099 | C9: =IS!C18+CF!C9+CF!C6 -> 1664229 | D9: =IS!D18+CF!D9+CF!D6 -> 1922758 | E9: =IS!E18+CF!E9+CF!E6 -> 3211245 | F9: =IS!F18+CF!F9+CF!F6 -> 5729052
A10: EV/EBITDA | B10: =B8/(B9*10^6) -> 2.3737358 | C10: =C8/(C9*10^6) -> 1.8609154 | D10: =D8/(D9*10^6) -> 3.6344033 | E10: =E8/(E9*10^6) -> 5.7040917 | F10: =F8/(F9*10^6) -> 2.4487631 | G10: 4.79 | H10: 7.48

Sheet Sheet1
B2: FCFF | C2: =FCFF!B18 -> 104911.59 | D2: 0.3
B3: FCFE | C3: =FCFE!B17 -> 84616.77 | D3: 0.3
B4: PE | C4: =PE!B7 -> 38250.448 | D4: 0.2
B5: PB | C5: =+PB!B9 -> 44603.736 | D5: 0.2
D6: =C2*D2+C3*D3+C4*D4+C5*D5 -> 73429.345 | F6: 33400
E8: =(F6-D6)/F6 -> -1.1984834
