Workbook
Name o28\: WC!$P$33

Sheet Valuation
A1: Minh Huyền | K1: Prepared by: TV
A2: Entity: | B2: SAB | K2: Reviewed by: LB
A3: Fiscal year: | B3: 46022 | K3: Date:
A4: Date of report: | B4: 45748
A8: Ticker | B8: SAB VN Equity | I8: Adjusted Beta | R8: Violet | S8: Other sheets
A9: Target Price | B9: =ROUND(E21,-2) -> 55700 | L9: WACC | M9: =M10*M11*(1+B15)+M13*M12 -> 0.10392437 | R9: Blue | S9: Input
A10: Upside | B10: =B9/B11-1 -> 0.25733634 | H10: Cost of Equity | J10: =J12+J11*J13 -> 0.104232 | L10: Cost of Debt | M10: =-Debt!N91 -> 0.078862231 | R10: Black | S10: Same sheet
A11: Current Price | B11: 44300 | H11: Beta | J11: 0.74 | L11: Weight of Debt | M11: =1-M13 -> 0.0076102448
A12: Outstanding share (bn) | B12: 1282 | H12: Rf | J12: 0.04 | L12: Cost of Equity | M12: =J10 -> 0.104232 | R12: Weighted Average Cost of Capital (WACC)
A13: Equity value | B13: =B12*B11 -> 56792600 | H13: Equity Risk Premium | J13: 0.0868 | L13: Weight of Equity | M13: =M14/(M14+M15) -> 0.99238976 | R13: WACC (%) | S13: =M9 -> 0.10392437
A14: Total debt | B14: =H73 -> 435520 | L14: MV of Equity | M14: =B13 -> 56792600 | R14: Risk-free rate (%) | S14: =J12 -> 0.04
A15: Tax rate | B15: ='1IS'!O47 -> -0.19087889 | L15: MV of Debt | M15: =B14 -> 435520 | R15: Equity risk premium (%) | S15: =J13 -> 0.0868
R16: Beta | S16: =J11 -> 0.74
B17: Tổng hợp định gía | R17: Debt cost (%) | S17: =M10 -> 0.078862231
D18: Weight | E18: Target Price | R18: The cost of equity(%) | S18: =M12 -> 0.104232
B19: FCFF | D19: 0.5 | E19: =D98 -> 57700 | R19: Debt-to-equity ratio | S19: =M15/M14 -> 0.0076686047
B20: P/E | D20: =1-D19 -> 0.5 | E20: =D124 -> 53657.891 | R20: Total debt | S20: =M15 -> 435520
B21: Total | D21: 1 | E21: =SUMPRODUCT(D19:D20,E19:E20) -> 55678.945
E25: =E27/D27 -> 1.2197259 | F25: =F27/E27 -> 0.91931284 | G25: =G27/F27 -> 0.79591403 | H25: =H27/G27 -> 1.3996872 | I25: =I27/H27 -> 0.77367441 | J25: =J27/I27 -> 1.056338 | K25: =K27/J27 -> 1.0174316 | L25: =L27/K27 -> 0.99691456 | ... N25: =N27/M27 -> 1.0954781
B26: FCFF | D26: 2018 | E26: 1019 | F26: 2020 | G26: 2021 | H26: 2022 | I26: 2023 | J26: 2024 | K26: 2025 | L26: 2026 | M26: 2027 | N26: 2028
B27: NI | D27: ='1IS'!H21 -> 4402750 | E27: ='1IS'!I21 -> 5370148 | F27: ='1IS'!J21 -> 4936846 | G27: ='1IS'!K21 -> 3929305 | H27: ='1IS'!L21 -> 5499798 | I27: ='1IS'!M21 -> 4255053 | J27: ='1IS'!N21 -> 4494774 | K27: ='1IS'!O21 -> 4573125 | ... N27: ='1IS'!R21 -> 5159881.4
A28: + | B28: NCC | I28: =SUM('1CF'!J8:J9) -> 573450 | J28: =SUM('1CF'!K8:K9) -> 553199 | K28: =SUM('1CF'!L8:L9) -> 772739 | L28: =SUM('1CF'!M8:M9) -> 547559.25 | M28: =SUM('1CF'!N8:N9) -> 722511.26 | N28: =SUM('1CF'!O8:O9) -> 870123.89
A29: + | B29: Int(1-t) | I29: =-'1IS'!M8*(1+$B$15) -> 40630.017 | J29: =-'1IS'!N8*(1+$B$15) -> 22210.374 | K29: =-'1IS'!O8*(1+$B$15) -> 27790.074 | L29: =-'1IS'!P8*(1+$B$15) -> 26885.738 | M29: =-'1IS'!Q8*(1+$B$15) -> 28257.776 | N29: =-'1IS'!R8*(1+$B$15) -> 30638.399
A30: - | B30: WCInv | I30: =-SUM('1CF'!J16:J19) -> 1108889 | J30: =-SUM('1CF'!K16:K19) -> -691269 | K30: =-SUM('1CF'!L16:L19) -> 38289 | L30: =-SUM('1CF'!M16:M19) -> 655074.92 | M30: =-SUM('1CF'!N16:N19) -> 85454.636 | N30: =-SUM('1CF'!O16:O19) -> -179069.22
A31: - | B31: Capex | I31: =-'1CF'!M21 -> 33228.324 | J31: =-'1CF'!N21 -> 34924.037 | K31: =-'1CF'!O21 -> 37866.271 | L31: =-'1CF'!P21 -> 39228.538 | M31: =-'1CF'!Q21 -> 41647.58 | N31: =-'1CF'!R21 -> 44356.65
B32: FCFF | I32: =I27+I28+I29-I30-I31 -> 3727015.7 | J32: =J27+J28+J29-J30-J31 -> 5726528.3 | K32: =K27+K28+K29-K30-K31 -> 5297498.8 | L32: =L27+L28+L29-L30-L31 -> 4439156.4 | M32: =M27+M28+M29-M30-M31 -> 5333830.9 | N32: =N27+N28+N29-N30-N31 -> 6195356.3
I34: =I26 -> 2023 | J34: =J26 -> 2024 | K34: =K26 -> 2025 | L34: =L26 -> 2026 | M34: =M26 -> 2027 | N34: =N26 -> 2028
B35: WACC | D35: =M9 -> 0.10392437
B36: Discount factor | J36: =1/((1+$D$35)^(J26-2020)) -> 0.67335287 | K36: =1/((1+$D$35)^(K26-2020)) -> 0.60996286 | L36: =1/((1+$D$35)^(L26-2020)) -> 0.55254044 | M36: =1/((1+$D$35)^(M26-2020)) -> 0.50052382 | N36: =1/((1+$D$35)^(N26-2020)) -> 0.45340408
B37: PV of FCFF | J37: =J32*J36 -> 3855974.3 | K37: =K32*K36 -> 3231277.5 | L37: =L32*L36 -> 2452813.5 | M37: =M32*M36 -> 2669709.4 | N37: =N32*N36 -> 2808999.8
B38: PV of Terminal Value | N38: =N37*(1+D48)/(D35-D48)*N36 -> 12255181
B48: Terminal Growth | D48: 0
B49: Enterprise Value (VND bn) | D49: =SUM(J37:N37)+N38 -> 27273956
B50: (-) Total Debt | D50: =Debt!K5+Debt!K13 -> 1033059 | E50: 2022
B51: (+) Cash&Cash Equivalents | D51: ='1BS'!L4 -> 4069464 | E51: 2022
B52: Minority int | D52: 0
B53: Implied Equity Value | D53: =D49-D50+D51 -> 30310361
B54: Share outstanding | D54: =B12 -> 1282
B55: Price per Share (VND) | D55: =D53/D54 -> 23643.027
B57: FCFF | I57: 2023 | J57: 2024 | K57: 2025 | L57: 2026 | M57: 2027 | N57: 2028 | O57: 2029 | P57: 2030 | Q57: 2031
...

Sheet 1BS
C1: Input | Y1: Var
C2: 2013 | D2: =C2+1 -> 2014 | E2: =D2+1 -> 2015 | F2: =E2+1 -> 2016 | G2: =F2+1 -> 2017 | H2: =G2+1 -> 2018 | I2: =H2+1 -> 2019 | J2: =I2+1 -> 2020 | K2: =J2+1 -> 2021 | ... U2: =T2+1 -> 2031 | V2: Note | X2: Code for CF | Y2: 2024 | Z2: 2025 | AA2: 2026 | AB2: 2027 | AC2: 2028 | AD2: 2029 | AE2: 2030 | AF2: 2031
A3: 100 | B3: CURRENT ASSETS | C3: =BS!G2 -> 8481709 | D3: =BS!H2 -> 10547147 | E3: =BS!I2 -> 12194294 | F3: =BS!J2 -> 10714346 | G3: =BS!K2 -> 13686327 | H3: =BS!L2 -> 14690168 | I3: =BS!M2 -> 19164603 | J3: =BS!N2 -> 19513381 | ... O3: =BS!S2 -> 22140978 | P3: =SUM(P4,P7,P11,P20,P23) -> 21786543 | Q3: =SUM(Q4,Q7,Q11,Q20,Q23) -> 22218601 | R3: =SUM(R4,R7,R11,R20,R23) -> 23752581 | S3: =SUM(S4,S7,S11,S20,S23) -> 24975052 | T3: =SUM(T4,T7,T11,T20,T23) -> 26566335 | U3: =SUM(U4,U7,U11,U20,U23) -> 27759472 | X3: x | Y3: =N3-M3 -> -1486673 | Z3: =O3-N3 -> -2925755 | AA3: =P3-O3 -> -354434.56 | AB3: =Q3-P3 -> 432057.81 | AC3: =R3-Q3 -> 1533979.8 | AD3: =S3-R3 -> 1222470.5 | AE3: =T3-S3 -> 1591283.5 | AF3: =U3-T3 -> 1193137.3
A4: 110 | B4: Cash and cash equivalents | C4: =BS!G3 -> 1848256 | D4: =BS!H3 -> 1817059 | E4: =BS!I3 -> 7935974 | F4: =BS!J3 -> 3444825 | G4: =BS!K3 -> 4268599 | H4: =BS!L3 -> 4467392 | I4: =BS!M3 -> 4115885 | J4: =BS!N3 -> 2726137 | ... O4: =BS!S3 -> 4016882 | P4: =SUM(P5:P6) -> 3747577.4 | Q4: =SUM(Q5:Q6) -> 4922413.3 | R4: =SUM(R5:R6) -> 6413066.7 | S4: =SUM(S5:S6) -> 7541761.5 | T4: =SUM(T5:T6) -> 9076879.8 | U4: =SUM(U5:U6) -> 9805123.4 | X4: x | Y4: =N4-M4 -> -562406 | Z4: =O4-N4 -> -460620 | AA4: =P4-O4 -> -269304.56 | AB4: =Q4-P4 -> 1174835.9 | AC4: =R4-Q4 -> 1490653.4 | AD4: =S4-R4 -> 1128694.8 | AE4: =T4-S4 -> 1535118.2 | AF4: =U4-T4 -> 728243.66
A5: 111 | B5: Cash | C5: =BS!G4 -> 740070 | D5: =BS!H4 -> 991789 | E5: =BS!I4 -> 746447 | F5: =BS!J4 -> 1067588 | G5: =BS!K4 -> 1631825 | H5: =BS!L4 -> 1595189 | I5: =BS!M4 -> 953479 | J5: =BS!N4 -> 844203 | ... O5: =BS!S4 -> 1174863 | P5: ='1CF'!M57 -> 3747577.4 | Q5: ='1CF'!N57 -> 4922413.3 | R5: ='1CF'!O57 -> 6413066.7 | S5: ='1CF'!P57 -> 7541761.5 | T5: ='1CF'!Q57 -> 9076879.8 | U5: ='1CF'!R57 -> 9805123.4 | X5: x | Y5: =N5-M5 -> -85288 | Z5: =O5-N5 -> -162898 | AA5: =P5-O5 -> 2572714.4 | AB5: =Q5-P5 -> 1174835.9 | AC5: =R5-Q5 -> 1490653.4 | AD5: =S5-R5 -> 1128694.8 | AE5: =T5-S5 -> 1535118.2 | AF5: =U5-T5 -> 728243.66
A6: 112 | B6: Cash equivalents | C6: =BS!G5 -> 1108185 | D6: =BS!H5 -> 825269 | E6: =BS!I5 -> 7189527 | F6: =BS!J5 -> 2377237 | G6: =BS!K5 -> 2636774 | H6: =BS!L5 -> 2872203 | I6: =BS!M5 -> 3162406 | J6: =BS!N5 -> 1881934 | ... O6: =BS!S5 -> 2842019 | P6: 0 | Q6: 0 | R6: 0 | S6: 0 | T6: 0 | U6: 0 | X6: x | Y6: =N6-M6 -> -477119 | Z6: =O6-N6 -> -297721 | AA6: =P6-O6 -> -2842019 | AB6: =Q6-P6 -> 0 | AC6: =R6-Q6 -> 0 | AD6: =S6-R6 -> 0 | AE6: =T6-S6 -> 0 | AF6: =U6-T6 -> 0
A7: 120 | B7: Short-term investments | C7: =BS!G6 -> 4054767 | D7: =BS!H6 -> 5719665 | E7: =BS!I6 -> 942767 | F7: =BS!J6 -> 3174321 | G7: =BS!K6 -> 6558801 | H7: =BS!L6 -> 7544188 | I7: =BS!M6 -> 12393227 | J7: =BS!N6 -> 14547419 | ... O7: =BS!S6 -> 14985489 | P7: =SUM(P8:P10) -> 14838769 | Q7: =SUM(Q8:Q10) -> 14108562 | R7: =SUM(R8:R10) -> 13884887 | S7: =SUM(S8:S10) -> 13930853 | T7: =SUM(T8:T10) -> 13869148 | U7: =SUM(U8:U10) -> 14213259 | V7: x | X7: x | Y7: =N7-M7 -> -1174813 | Z7: =O7-N7 -> -1580750 | AA7: =P7-O7 -> -146720.03 | AB7: =Q7-P7 -> -730207.4 | AC7: =R7-Q7 -> -223674.78 | AD7: =S7-R7 -> 45966.644 | AE7: =T7-S7 -> -61705.126 | AF7: =U7-T7 -> 344110.95
A8: 121 | B8: Short-term investments | C8: =BS!G7 -> 0 | D8: =BS!H7 -> 0 | E8: =BS!I7 -> 0 | F8: =BS!J7 -> 0 | G8: =BS!K7 -> 0 | H8: =BS!L7 -> 0 | I8: =BS!M7 -> 0 | J8: =BS!N7 -> 0 | ... O8: =BS!S7 -> 0 | P8: =WC!O4 -> 0 | Q8: =WC!P4 -> 0 | R8: =WC!Q4 -> 0 | S8: =WC!R4 -> 0 | T8: =WC!S4 -> 0 | U8: =WC!T4 -> 0 | X8: 23 | Y8: =N8-M8 -> 0 | Z8: =O8-N8 -> 0 | AA8: =P8-O8 -> 0 | AB8: =Q8-P8 -> 0 | AC8: =R8-Q8 -> 0 | AD8: =S8-R8 -> 0 | AE8: =T8-S8 -> 0 | AF8: =U8-T8 -> 0
A9: 122 | B9: Provision for diminution | C9: =BS!G8 -> 0 | D9: =BS!H8 -> 0 | E9: =BS!I8 -> 0 | F9: =BS!J8 -> 0 | G9: =BS!K8 -> 0 | H9: =BS!L8 -> 0 | I9: =BS!M8 -> 0 | J9: =BS!N8 -> 0 | ... O9: =BS!S8 -> 0 | P9: =WC!O5 -> 0 | Q9: =WC!P5 -> 0 | R9: =WC!Q5 -> 0 | S9: =WC!R5 -> 0 | T9: =WC!S5 -> 0 | U9: =WC!T5 -> 0 | X9: 3 | Y9: =N9-M9 -> 0 | Z9: =O9-N9 -> 0 | AA9: =P9-O9 -> 0 | AB9: =Q9-P9 -> 0 | AC9: =R9-Q9 -> 0 | AD9: =S9-R9 -> 0 | AE9: =T9-S9 -> 0 | AF9: =U9-T9 -> 0
A10: 123 | B10: Held-to-maturity investment | C10: =BS!G9 -> 4054767 | D10: =BS!H9 -> 5719665 | E10: =BS!I9 -> 942767 | F10: =BS!J9 -> 3174321 | G10: =BS!K9 -> 6558801 | H10: =BS!L9 -> 7544188 | I10: =BS!M9 -> 12393227 | J10: =BS!N9 -> 14547419 | ... O10: =BS!S9 -> 14985489 | P10: =WC!O6 -> 14838769 | Q10: =WC!P6 -> 14108562 | R10: =WC!Q6 -> 13884887 | S10: =WC!R6 -> 13930853 | T10: =WC!S6 -> 13869148 | U10: =WC!T6 -> 14213259 | X10: 23 | Y10: =N10-M10 -> -1174813 | Z10: =O10-N10 -> -1580750 | AA10: =P10-O10 -> -146720.03 | AB10: =Q10-P10 -> -730207.4 | AC10: =R10-Q10 -> -223674.78 | AD10: =S10-R10 -> 45966.644 | AE10: =T10-S10 -> -61705.126 | AF10: =U10-T10 -> 344110.95
A11: 130 | B11: Accounts receivable | C11: =BS!G10 -> 766054 | D11: =BS!H10 -> 1031471 | E11: =BS!I10 -> 1085027 | F11: =BS!J10 -> 1090133 | G11: =BS!K10 -> 715326 | H11: =BS!L10 -> 765631 | I11: =BS!M10 -> 568608 | J11: =BS!N10 -> 590846 | ... O11: =BS!S10 -> 902823 | P11: =SUM(P12:P19) -> 1047528.8 | Q11: =SUM(Q12:Q19) -> 1015073.3 | R11: =SUM(R12:R19) -> 1093678 | S11: =SUM(S12:S19) -> 1131510.5 | T11: =SUM(T12:T19) -> 1152919.5 | U11: =SUM(U12:U19) -> 1196605.3 | V11: x | X11: x | Y11: =N11-M11 -> 589071 | Z11: =O11-N11 -> -915649 | AA11: =P11-O11 -> 144705.85 | AB11: =Q11-P11 -> -32455.544 | AC11: =R11-Q11 -> 78604.717 | AD11: =S11-R11 -> 37832.434 | AE11: =T11-S11 -> 21409.059 | AF11: =U11-T11 -> 43685.798
A12: 131 | B12: Trade accounts receivable | C12: =BS!G11 -> 546565 | D12: =BS!H11 -> 551396 | E12: =BS!I11 -> 621408 | F12: =BS!J11 -> 551219 | G12: =BS!K11 -> 171321 | H12: =BS!L11 -> 244119 | I12: =BS!M11 -> 157655 | J12: =BS!N11 -> 69332 | ... O12: =BS!S11 -> 697568 | P12: =WC!O8 -> 503153.95 | Q12: =WC!P8 -> 387817.98 | R12: =WC!Q8 -> 472563.18 | S12: =WC!R8 -> 484230.26 | T12: =WC!S8 -> 479745.04 | U12: =WC!T8 -> 507907.95 | X12: 9 | Y12: =N12-M12 -> -34226 | Z12: =O12-N12 -> 264427 | AA12: =P12-O12 -> -194414.05 | AB12: =Q12-P12 -> -115335.96 | AC12: =R12-Q12 -> 84745.195 | AD12: =S12-R12 -> 11667.082 | AE12: =T12-S12 -> -4485.2134 | AF12: =U12-T12 -> 28162.907
A13: 132 | B13: Prepayments to suppliers | C13: =BS!G12 -> 160999 | D13: =BS!H12 -> 133998 | E13: =BS!I12 -> 71472 | F13: =BS!J12 -> 166785 | G13: =BS!K12 -> 108550 | H13: =BS!L12 -> 74758 | I13: =BS!M12 -> 54679 | J13: =BS!N12 -> 164204 | ... O13: =BS!S12 -> 31631 | P13: =WC!O9 -> 34511.464 | Q13: =WC!P9 -> 37098.206 | R13: =WC!Q9 -> 37066.296 | S13: =WC!R9 -> 38552.431 | T13: =WC!S9 -> 40308.371 | U13: =WC!T9 -> 40956.534 | X13: 9 | Y13: =N13-M13 -> 15109 | Z13: =O13-N13 -> -16760 | AA13: =P13-O13 -> 2880.4644 | AB13: =Q13-P13 -> 2586.7418 | AC13: =R13-Q13 -> -31.909818 | AD13: =S13-R13 -> 1486.1344 | AE13: =T13-S13 -> 1755.9399 | AF13: =U13-T13 -> 648.16333
A14: 133 | B14: Intercompany receivables | C14: =BS!G13 -> 0 | D14: =BS!H13 -> 0 | E14: =BS!I13 -> 0 | F14: =BS!J13 -> 0 | G14: =BS!K13 -> 0 | H14: =BS!L13 -> 0 | I14: =BS!M13 -> 0 | J14: =BS!N13 -> 0 | ... O14: =BS!S13 -> 0 | P14: =WC!O10 -> 0 | Q14: =WC!P10 -> 0 | R14: =WC!Q10 -> 0 | S14: =WC!R10 -> 0 | T14: =WC!S10 -> 0 | U14: =WC!T10 -> 0 | X14: 9 | Y14: =N14-M14 -> 0 | Z14: =O14-N14 -> 0 | AA14: =P14-O14 -> 0 | AB14: =Q14-P14 -> 0 | AC14: =R14-Q14 -> 0 | AD14: =S14-R14 -> 0 | AE14: =T14-S14 -> 0 | AF14: =U14-T14 -> 0
A15: 134 | B15: Construction contract in progress receivables | C15: =BS!G14 -> 0 | D15: =BS!H14 -> 0 | E15: =BS!I14 -> 0 | F15: =BS!J14 -> 0 | G15: =BS!K14 -> 0 | H15: =BS!L14 -> 0 | I15: =BS!M14 -> 0 | J15: =BS!N14 -> 0 | ... O15: =BS!S14 -> 0 | P15: =WC!O11 -> 0 | Q15: =WC!P11 -> 0 | R15: =WC!Q11 -> 0 | S15: =WC!R11 -> 0 | T15: =WC!S11 -> 0 | U15: =WC!T11 -> 0 | X15: 0 | Y15: =N15-M15 -> 0 | Z15: =O15-N15 -> 0 | AA15: =P15-O15 -> 0 | AB15: =Q15-P15 -> 0 | AC15: =R15-Q15 -> 0 | AD15: =S15-R15 -> 0 | AE15: =T15-S15 -> 0 | AF15: =U15-T15 -> 0
A16: 135 | B16: Short-term loans receivables | C16: =BS!G15 -> 0 | D16: =BS!H15 -> 0 | E16: =BS!I15 -> 0 | F16: =BS!J15 -> 0 | G16: =BS!K15 -> 0 | H16: =BS!L15 -> 502625 | I16: =BS!M15 -> 0 | J16: =BS!N15 -> 0 | ... O16: =BS!S15 -> 0 | P16: =WC!O12 -> 0 | Q16: =WC!P12 -> 0 | R16: =WC!Q12 -> 0 | S16: =WC!R12 -> 0 | T16: =WC!S12 -> 0 | U16: =WC!T12 -> 0 | X16: 9 | Y16: =N16-M16 -> 0 | Z16: =O16-N16 -> 0 | AA16: =P16-O16 -> 0 | AB16: =Q16-P16 -> 0 | AC16: =R16-Q16 -> 0 | AD16: =S16-R16 -> 0 | AE16: =T16-S16 -> 0 | AF16: =U16-T16 -> 0
A17: 136 | B17: Other receivables | C17: =BS!G16 -> 103703 | D17: =BS!H16 -> 391899 | E17: =BS!I16 -> 440463 | F17: =BS!J16 -> 421976 | G17: =BS!K16 -> 488911 | H17: =BS!L16 -> -55871 | I17: =BS!M16 -> 702587 | J17: =BS!N16 -> 699600 | ... O17: =BS!S16 -> 746762 | P17: =WC!O13 -> 843903.66 | Q17: =WC!P13 -> 832227.04 | R17: =WC!Q13 -> 887637.38 | S17: =WC!R13 -> 900667.56 | T17: =WC!S13 -> 941211.16 | U17: =WC!T13 -> 962196.73 | X17: 9 | Y17: =N17-M17 -> 621921 | Z17: =O17-N17 -> -899716 | AA17: =P17-O17 -> 97141.665 | AB17: =Q17-P17 -> -11676.625 | AC17: =R17-Q17 -> 55410.336 | AD17: =S17-R17 -> 13030.182 | AE17: =T17-S17 -> 40543.601 | AF17: =U17-T17 -> 20985.567
A18: 137 | B18: Provision for doubtful debts | C18: =BS!G17 -> -45213 | D18: =BS!H17 -> -45822 | E18: =BS!I17 -> -48316 | F18: =BS!J17 -> -49846 | G18: =BS!K17 -> -53456 | H18: =BS!L17 -> 0 | I18: =BS!M17 -> -346313 | J18: =BS!N17 -> -342290 | ... O18: =BS!S17 -> -573138 | P18: =WC!O14 -> -334040.23 | Q18: =WC!P14 -> -242069.92 | R18: =WC!Q14 -> -303588.83 | S18: =WC!R14 -> -291939.79 | T18: =WC!S14 -> -308345.06 | U18: =WC!T14 -> -314455.9 | X18: 3 | Y18: =N18-M18 -> -13734 | Z18: =O18-N18 -> -263600 | AA18: =P18-O18 -> 239097.77 | AB18: =Q18-P18 -> 91970.304 | AC18: =R18-Q18 -> -61518.905 | AD18: =S18-R18 -> 11649.035 | AE18: =T18-S18 -> -16405.268 | AF18: =U18-T18 -> -6110.8388
A19: 139 | B19: Shortage of current assets waiting for solution | C19: 0 | D19: 0 | E19: 0 | F19: 0 | G19: 0 | H19: 0 | I19: 0 | J19: 0 | K19: 0 | L19: 0 | M19: 0 | N19: 0 | O19: 0 | P19: =WC!O15 -> 0 | Q19: =WC!P15 -> 0 | R19: =WC!Q15 -> 0 | S19: =WC!R15 -> 0 | T19: =WC!S15 -> 0 | U19: =WC!T15 -> 0 | X19: 0 | Y19: =N19-M19 -> 0 | Z19: =O19-N19 -> 0 | AA19: =P19-O19 -> 0 | AB19: =Q19-P19 -> 0 | AC19: =R19-Q19 -> 0 | AD19: =S19-R19 -> 0 | AE19: =T19-S19 -> 0 | AF19: =U19-T19 -> 0
A20: 140 | B20: Inventories | C20: =BS!G18 -> 1686954 | D20: =BS!H18 -> 1868972 | E20: =BS!I18 -> 1924904 | F20: =BS!J18 -> 2126217 | G20: =BS!K18 -> 2003535 | H20: =BS!L18 -> 1813754 | I20: =BS!M18 -> 1967138 | J20: =BS!N18 -> 1446833 | ... O20: =BS!S18 -> 2027352 | P20: =SUM(P21:P22) -> 1949659 | Q20: =SUM(Q21:Q22) -> 1963349.4 | R20: =SUM(R21:R22) -> 2137713.7 | S20: =SUM(S21:S22) -> 2145593.4 | T20: =SUM(T21:T22) -> 2232284.9 | U20: =SUM(U21:U22) -> 2302870 | V20: x | X20: x | Y20: =N20-M20 -> -338961 | Z20: =O20-N20 -> 48808 | AA20: =P20-O20 -> -77693.032 | AB20: =Q20-P20 -> 13690.436 | AC20: =R20-Q20 -> 174364.25 | AD20: =S20-R20 -> 7879.7487 | AE20: =T20-S20 -> 86691.511 | AF20: =U20-T20 -> 70585.091
A21: 141 | B21: Inventories | C21: =BS!G19 -> 1733089 | D21: =BS!H19 -> 1909069 | E21: =BS!I19 -> 1960526 | F21: =BS!J19 -> 2171045 | G21: =BS!K19 -> 2116546 | H21: =BS!L19 -> 2034064 | I21: =BS!M19 -> 2169541 | J21: =BS!N19 -> 1525039 | ... O21: =BS!S19 -> 2109850 | P21: =WC!O17 -> 2018394.7 | Q21: =WC!P17 -> 2034303.2 | R21: =WC!Q17 -> 2217571.9 | S21: =WC!R17 -> 2223370.5 | T21: =WC!S17 -> 2313945.5 | U21: =WC!T17 -> 2387452.5 | X21: 10 | Y21: =N21-M21 -> -350232 | Z21: =O21-N21 -> 66997 | AA21: =P21-O21 -> -91455.261 | AB21: =Q21-P21 -> 15908.465 | AC21: =R21-Q21 -> 183268.69 | AD21: =S21-R21 -> 5798.6514 | AE21: =T21-S21 -> 90574.954 | AF21: =U21-T21 -> 73507.039
A22: 149 | B22: Provision for decline in inventories | C22: =BS!G20 -> -46135 | D22: =BS!H20 -> -40097 | E22: =BS!I20 -> -35622 | F22: =BS!J20 -> -44828 | G22: =BS!K20 -> -113011 | H22: =BS!L20 -> -220310 | I22: =BS!M20 -> -202403 | J22: =BS!N20 -> -78206 | ... O22: =BS!S20 -> -82498 | P22: =WC!O18 -> -68735.771 | Q22: =WC!P18 -> -70953.8 | R22: =WC!Q18 -> -79858.242 | S22: =WC!R18 -> -77777.144 | T22: =WC!S18 -> -81660.588 | U22: =WC!T18 -> -84582.536 | X22: 3 | Y22: =N22-M22 -> 11271 | Z22: =O22-N22 -> -18189 | AA22: =P22-O22 -> 13762.229 | AB22: =Q22-P22 -> -2218.0287 | AC22: =R22-Q22 -> -8904.442 | AD22: =S22-R22 -> 2081.0973 | AE22: =T22-S22 -> -3883.4434 | AF22: =U22-T22 -> -2921.9484
A23: 150 | B23: Other current assets | C23: =BS!G21 -> 125679 | D23: =BS!H21 -> 109981 | E23: =BS!I21 -> 305623 | F23: =BS!J21 -> 878849 | G23: =BS!K21 -> 140066 | H23: =BS!L21 -> 99203 | I23: =BS!M21 -> 119745 | J23: =BS!N21 -> 202146 | ... O23: =BS!S21 -> 208433 | P23: =SUM(P24:P28) -> 203009.22 | Q23: =SUM(Q24:Q28) -> 209203.65 | R23: =SUM(R24:R28) -> 223235.91 | S23: =SUM(S24:S28) -> 225332.75 | T23: =SUM(T24:T28) -> 235102.58 | U23: =SUM(U24:U28) -> 241614.34 | V23: x | X23: x | Y23: =N23-M23 -> 437 | Z23: =O23-N23 -> -17543 | AA23: =P23-O23 -> -5423.7817 | AB23: =Q23-P23 -> 6194.4272 | AC23: =R23-Q23 -> 14032.269 | AD23: =S23-R23 -> 2096.8335 | AE23: =T23-S23 -> 9769.8287 | AF23: =U23-T23 -> 6511.7649
A24: 151 | B24: Short-term prepaid expenses | C24: =BS!G22 -> 26156 | D24: =BS!H22 -> 31533 | E24: =BS!I22 -> 128076 | F24: =BS!J22 -> 67695 | G24: =BS!K22 -> 24913 | H24: =BS!L22 -> 86457 | I24: =BS!M22 -> 97130 | J24: =BS!N22 -> 143822 | ... O24: =BS!S22 -> 139821 | P24: =WC!O20 -> 140696.45 | Q24: =WC!P20 -> 140163.33 | R24: =WC!Q20 -> 151303.72 | S24: =WC!R20 -> 153278.97 | T24: =WC!S20 -> 158933.39 | U24: =WC!T20 -> 163815.81 | X24: 12 | Y24: =N24-M24 -> -26572 | Z24: =O24-N24 -> -5839 | AA24: =P24-O24 -> 875.45063 | AB24: =Q24-P24 -> -533.1164 | AC24: =R24-Q24 -> 11140.384 | AD24: =S24-R24 -> 1975.2509 | AE24: =T24-S24 -> 5654.4197 | AF24: =U24-T24 -> 4882.4192
A25: 152 | B25: VAT to be claimed | C25: =BS!G23 -> 64106 | D25: =BS!H23 -> 32289 | E25: =BS!I23 -> 70980 | F25: =BS!J23 -> 133497 | G25: =BS!K23 -> 112192 | H25: =BS!L23 -> 7565 | I25: =BS!M23 -> 18204 | J25: =BS!N23 -> 22192 | ... O25: =BS!S23 -> 58809 | P25: =WC!O21 -> 52376.791 | Q25: =WC!P21 -> 59770.973 | R25: =WC!Q21 -> 61492.928 | S25: =WC!R21 -> 61537.846 | T25: =WC!S21 -> 65373.227 | U25: =WC!T21 -> 66575.144 | X25: 9 | Y25: =N25-M25 -> 33043 | Z25: =O25-N25 -> -13303 | AA25: =P25-O25 -> -6432.2092 | AB25: =Q25-P25 -> 7394.1826 | AC25: =R25-Q25 -> 1721.9549 | AD25: =S25-R25 -> 44.918082 | AE25: =T25-S25 -> 3835.3809 | AF25: =U25-T25 -> 1201.9163
A26: 153 | B26: Other taxes receivable | C26: =BS!G24 -> 9186 | D26: =BS!H24 -> 11025 | E26: =BS!I24 -> 106510 | F26: =BS!J24 -> 677657 | G26: =BS!K24 -> 2961 | H26: =BS!L24 -> 5182 | I26: =BS!M24 -> 4411 | J26: =BS!N24 -> 36132 | ... O26: =BS!S24 -> 9803 | P26: =WC!O22 -> 9935.977 | Q26: =WC!P22 -> 9269.3379 | R26: =WC!Q22 -> 10439.268 | S26: =WC!R22 -> 10515.932 | T26: =WC!S22 -> 10795.96 | U26: =WC!T22 -> 11223.39 | X26: 9 | Y26: =N26-M26 -> -6035 | Z26: =O26-N26 -> 1600 | AA26: =P26-O26 -> 132.97695 | AB26: =Q26-P26 -> -666.63905 | AC26: =R26-Q26 -> 1169.93 | AD26: =S26-R26 -> 76.664456 | AE26: =T26-S26 -> 280.02811 | AF26: =U26-T26 -> 427.42936
A27: 154 | B27: Government bonds purchased for resale | C27: =BS!G25 -> 0 | D27: =BS!H25 -> 0 | E27: =BS!I25 -> 0 | F27: =BS!J25 -> 0 | G27: =BS!K25 -> 0 | H27: =BS!L25 -> 0 | I27: =BS!M25 -> 0 | J27: =BS!N25 -> 0 | ... O27: =BS!S25 -> 0 | P27: =WC!O23 -> 0 | Q27: =WC!P23 -> 0 | R27: =WC!Q23 -> 0 | S27: =WC!R23 -> 0 | T27: =WC!S23 -> 0 | U27: =WC!T23 -> 0 | X27: 0 | Y27: =N27-M27 -> 0 | Z27: =O27-N27 -> 0 | AA27: =P27-O27 -> 0 | AB27: =Q27-P27 -> 0 | AC27: =R27-Q27 -> 0 | AD27: =S27-R27 -> 0 | AE27: =T27-S27 -> 0 | AF27: =U27-T27 -> 0
A28: 158 | B28: Other current assets | C28: =BS!G26 -> 26231 | D28: =BS!H26 -> 35134 | E28: =BS!I26 -> 57 | F28: =BS!J26 -> 0 | G28: =BS!K26 -> 0 | H28: =BS!L26 -> 0 | I28: =BS!M26 -> 0 | J28: =BS!N26 -> 0 | ... O28: =BS!S26 -> 0 | P28: =WC!O24 -> 0 | Q28: =WC!P24 -> 0 | R28: =WC!Q24 -> 0 | S28: =WC!R24 -> 0 | T28: =WC!S24 -> 0 | U28: =WC!T24 -> 0 | X28: 12 | Y28: =N28-M28 -> 0 | Z28: =O28-N28 -> 0 | AA28: =P28-O28 -> 0 | AB28: =Q28-P28 -> 0 | AC28: =R28-Q28 -> 0 | AD28: =S28-R28 -> 0 | AE28: =T28-S28 -> 0 | AF28: =U28-T28 -> 0
A29: 200 | B29: LONG-TERM ASSETS | C29: =BS!G27 -> 10333058 | D29: =BS!H27 -> 11126890 | E29: =BS!I27 -> 9377631 | F29: =BS!J27 -> 8478519 | G29: =BS!K27 -> 8327362 | H29: =BS!L27 -> 7676575 | I29: =BS!M27 -> 7797874 | J29: =BS!N27 -> 7861591 | ... O29: =BS!S27 -> 10456376 | P29: =SUM(P30,P38,P49,P52,P55,P61,P62) -> 9606126.3 | Q29: =SUM(Q30,Q38,Q49,Q52,Q55,Q61,Q62) -> 8806631.5 | R29: =SUM(R30,R38,R49,R52,R55,R61,R62) -> 8079045.8 | S29: =SUM(S30,S38,S49,S52,S55,S61,S62) -> 7323568.2 | T29: =SUM(T30,T38,T49,T52,T55,T61,T62) -> 6760023.4 | U29: =SUM(U30,U38,U49,U52,U55,U61,U62) -> 6722987.1 | X29: x | Y29: =N29-M29 -> 869455 | Z29: =O29-N29 -> 2083702 | AA29: =P29-O29 -> -850249.68 | AB29: =Q29-P29 -> -799494.82 | AC29: =R29-Q29 -> -727585.69 | AD29: =S29-R29 -> -755477.56 | AE29: =T29-S29 -> -563544.86 | AF29: =U29-T29 -> -37036.323
A30: 210 | B30: Long-term trade receivables | C30: =BS!G28 -> 34 | D30: =BS!H28 -> 8000 | E30: =BS!I28 -> 34495 | F30: =BS!J28 -> 38349 | G30: =BS!K28 -> 20094 | H30: =BS!L28 -> 5861 | I30: =BS!M28 -> 9110 | J30: =BS!N28 -> 11958 | ... O30: =BS!S28 -> 34949 | P30: =O30 -> 34949 | Q30: =P30 -> 34949 | R30: =Q30 -> 34949 | S30: =R30 -> 34949 | T30: =S30 -> 34949 | U30: =T30 -> 34949 | V30: x | X30: x | Y30: =N30-M30 -> -737 | Z30: =O30-N30 -> 984 | AA30: =P30-O30 -> 0 | AB30: =Q30-P30 -> 0 | AC30: =R30-Q30 -> 0 | AD30: =S30-R30 -> 0 | AE30: =T30-S30 -> 0 | AF30: =U30-T30 -> 0
A31: 211 | B31: Long-term trade receivables from customers | C31: =BS!G29 -> 0 | D31: =BS!H29 -> 0 | E31: =BS!I29 -> 0 | F31: =BS!J29 -> 5317 | G31: =BS!K29 -> 4761 | H31: =BS!L29 -> 6078 | I31: =BS!M29 -> 6005 | J31: =BS!N29 -> 5988 | ... O31: =BS!S29 -> 5949 | P31: =O31 -> 5949 | Q31: =P31 -> 5949 | R31: =Q31 -> 5949 | S31: =R31 -> 5949 | T31: =S31 -> 5949 | U31: =T31 -> 5949 | X31: 9 | Y31: =N31-M31 -> 0 | Z31: =O31-N31 -> 0 | AA31: =P31-O31 -> 0 | AB31: =Q31-P31 -> 0 | AC31: =R31-Q31 -> 0 | AD31: =S31-R31 -> 0 | AE31: =T31-S31 -> 0 | AF31: =U31-T31 -> 0
A32: 212 | B32: Long-term prepayments to suppliers | C32: =BS!G30 -> 0 | D32: =BS!H30 -> 0 | E32: =BS!I30 -> 0 | F32: =BS!J30 -> 0 | G32: =BS!K30 -> 0 | H32: =BS!L30 -> 0 | I32: =BS!M30 -> 0 | J32: =BS!N30 -> 0 | ... O32: =BS!S30 -> 0 | P32: =O32 -> 0 | Q32: =P32 -> 0 | R32: =Q32 -> 0 | S32: =R32 -> 0 | T32: =S32 -> 0 | U32: =T32 -> 0 | X32: 9 | Y32: =N32-M32 -> 0 | Z32: =O32-N32 -> 0 | AA32: =P32-O32 -> 0 | AB32: =Q32-P32 -> 0 | AC32: =R32-Q32 -> 0 | AD32: =S32-R32 -> 0 | AE32: =T32-S32 -> 0 | AF32: =U32-T32 -> 0
A33: 213 | B33: Paid-in capital in wholly-owned subsidiaries | C33: 0 | D33: 0 | E33: 0 | F33: 0 | G33: 0 | H33: 0 | I33: 0 | J33: 0 | K33: 0 | L33: 0 | M33: 0 | N33: 0 | O33: 0 | P33: =O33 -> 0 | Q33: =P33 -> 0 | R33: =Q33 -> 0 | S33: =R33 -> 0 | T33: =S33 -> 0 | U33: =T33 -> 0 | X33: 9 | Y33: =N33-M33 -> 0 | Z33: =O33-N33 -> 0 | AA33: =P33-O33 -> 0 | AB33: =Q33-P33 -> 0 | AC33: =R33-Q33 -> 0 | AD33: =S33-R33 -> 0 | AE33: =T33-S33 -> 0 | AF33: =U33-T33 -> 0
A34: 214 | B34: Long-term intercompany receivables | C34: =BS!G31 -> 0 | D34: =BS!H31 -> 0 | E34: =BS!I31 -> 0 | F34: =BS!J31 -> 0 | G34: =BS!K31 -> 0 | H34: =BS!L31 -> 0 | I34: =BS!M31 -> 0 | J34: =BS!N31 -> 0 | ... O34: =BS!S31 -> 0 | P34: =O34 -> 0 | Q34: =P34 -> 0 | R34: =Q34 -> 0 | S34: =R34 -> 0 | T34: =S34 -> 0 | U34: =T34 -> 0 | X34: 9 | Y34: =N34-M34 -> 0 | Z34: =O34-N34 -> 0 | AA34: =P34-O34 -> 0 | AB34: =Q34-P34 -> 0 | AC34: =R34-Q34 -> 0 | AD34: =S34-R34 -> 0 | AE34: =T34-S34 -> 0 | AF34: =U34-T34 -> 0
A35: 215 | B35: Long-term loans receivables | C35: =BS!G32 -> 0 | D35: =BS!H32 -> 0 | E35: =BS!I32 -> 4000 | F35: =BS!J32 -> 4000 | G35: =BS!K32 -> 4000 | H35: =BS!L32 -> 4000 | I35: =BS!M32 -> 4000 | J35: =BS!N32 -> 4000 | ... O35: =BS!S32 -> 0 | P35: =O35 -> 0 | Q35: =P35 -> 0 | R35: =Q35 -> 0 | S35: =R35 -> 0 | T35: =S35 -> 0 | U35: =T35 -> 0 | X35: 9 | Y35: =N35-M35 -> 0 | Z35: =O35-N35 -> 0 | AA35: =P35-O35 -> 0 | AB35: =Q35-P35 -> 0 | AC35: =R35-Q35 -> 0 | AD35: =S35-R35 -> 0 | AE35: =T35-S35 -> 0 | AF35: =U35-T35 -> 0
A36: 216 | B36: Other long-term receivables | C36: =BS!G33 -> 34 | D36: =BS!H33 -> 8000 | E36: =BS!I33 -> 42495 | F36: =BS!J33 -> 46504 | G36: =BS!K33 -> 49119 | H36: =BS!L33 -> 35181 | I36: =BS!M33 -> 38495 | J36: =BS!N33 -> 41278 | ... O36: =BS!S33 -> 35400 | P36: =O36 -> 35400 | Q36: =P36 -> 35400 | R36: =Q36 -> 35400 | S36: =R36 -> 35400 | T36: =S36 -> 35400 | U36: =T36 -> 35400 | X36: 9 | Y36: =N36-M36 -> -737 | Z36: =O36-N36 -> 984 | AA36: =P36-O36 -> 0 | AB36: =Q36-P36 -> 0 | AC36: =R36-Q36 -> 0 | AD36: =S36-R36 -> 0 | AE36: =T36-S36 -> 0 | AF36: =U36-T36 -> 0
A37: 219 | B37: Provision for doubtful LT receivable | C37: =BS!G34 -> 0 | D37: =BS!H34 -> 0 | E37: =BS!I34 -> -12000 | F37: =BS!J34 -> -17472 | G37: =BS!K34 -> -37786 | H37: =BS!L34 -> -39398 | I37: =BS!M34 -> -39390 | J37: =BS!N34 -> -39308 | ... O37: =BS!S34 -> -6400 | P37: =O37 -> -6400 | Q37: =P37 -> -6400 | R37: =Q37 -> -6400 | S37: =R37 -> -6400 | T37: =S37 -> -6400 | U37: =T37 -> -6400 | X37: 3 | Y37: =N37-M37 -> 0 | Z37: =O37-N37 -> 0 | AA37: =P37-O37 -> 0 | AB37: =Q37-P37 -> 0 | AC37: =R37-Q37 -> 0 | AD37: =S37-R37 -> 0 | AE37: =T37-S37 -> 0 | AF37: =U37-T37 -> 0
A38: 220 | B38: Fixed assets | C38: =BS!G35 -> 6099450 | D38: =BS!H35 -> 7033461 | E38: =BS!I35 -> 5854864 | F38: =BS!J35 -> 5462594 | G38: =BS!K35 -> 5008100 | H38: =BS!L35 -> 4567091 | I38: =BS!M35 -> 4685440 | J38: =BS!N35 -> 4874504 | ... O38: =BS!S35 -> 5068260 | P38: =SUM(P39,P42,P45,P48) -> 4374176.1 | Q38: =SUM(Q39,Q42,Q45,Q48) -> 3531907.7 | R38: =SUM(R39,R42,R45,R48) -> 2774676.7 | S38: =SUM(S39,S42,S45,S48) -> 1999346.5 | T38: =SUM(T39,T42,T45,T48) -> 1409046.2 | U38: =SUM(U39,U42,U45,U48) -> 1346659.2 | V38: x | X38: x | Y38: =N38-M38 -> -376470 | Z38: =O38-N38 -> 1475006 | AA38: =P38-O38 -> -694083.86 | AB38: =Q38-P38 -> -842268.41 | AC38: =R38-Q38 -> -757231 | AD38: =S38-R38 -> -775330.2 | AE38: =T38-S38 -> -590300.33 | AF38: =U38-T38 -> -62387.012
A39: 221 | B39: Tangible fixed assets | C39: =BS!G36 -> 4455186 | D39: =BS!H36 -> 4915799 | E39: =BS!I36 -> 4843869 | F39: =BS!J36 -> 4478037 | G39: =BS!K36 -> 4044747 | H39: =BS!L36 -> 3614851 | I39: =BS!M36 -> 3743643 | J39: =BS!N36 -> 3753389 | ... O39: =BS!S36 -> 3492859 | P39: =SUM(P40:P41) -> 2827289 | Q39: =SUM(Q40:Q41) -> 2009923 | R39: =SUM(R40:R41) -> 1253204.3 | S39: =SUM(S40:S41) -> 487055.88 | T39: =SUM(T40:T41) -> -93218.104 | U39: =SUM(U40:U41) -> -143137.5 | X39: 0 | Y39: =N39-M39 -> -405499 | Z39: =O39-N39 -> 1008749 | AA39: =P39-O39 -> -665570.01 | AB39: =Q39-P39 -> -817365.95 | AC39: =R39-Q39 -> -756718.74 | AD39: =S39-R39 -> -766148.42 | AE39: =T39-S39 -> -580273.99 | AF39: =U39-T39 -> -49919.393
A40: 222 | B40: Cost | C40: =BS!G37 -> 7482669 | D40: =BS!H37 -> 8472996 | E40: =BS!I37 -> 9001467 | F40: =BS!J37 -> 9163284 | G40: =BS!K37 -> 9343836 | H40: =BS!L37 -> 9497450 | I40: =BS!M37 -> 10190231 | J40: =BS!N37 -> 10774957 | ... O40: =BS!S37 -> 16040238 | P40: =FA!O10 -> 16119753 | Q40: =FA!P10 -> 16059106 | R40: =FA!Q10 -> 16068535 | S40: =FA!R10 -> 16079057 | T40: =FA!S10 -> 16090157 | U40: =FA!T10 -> 16100972 | X40: 21 | Y40: =N40-M40 -> 79515 | Z40: =O40-N40 -> 4472406 | AA40: =P40-O40 -> 79515 | AB40: =Q40-P40 -> -60647.213 | AC40: =R40-Q40 -> 9429.6855 | AD40: =S40-R40 -> 10521.305 | AE40: =T40-S40 -> 11100.615 | AF40: =U40-T40 -> 10814.617 | AG40: Tangible assets
...

Sheet 1IS
W1: Growth rate
C2: 2013 | D2: =C2+1 -> 2014 | E2: =D2+1 -> 2015 | F2: =E2+1 -> 2016 | G2: =F2+1 -> 2017 | H2: 2018 | I2: =H2+1 -> 2019 | J2: =I2+1 -> 2020 | K2: =J2+1 -> 2021 | L2: =K2+1 -> 2022 | M2: =L2+1 -> 2023 | N2: =M2+1 -> 2024 | O2: =N2+1 -> 2025 | P2: ="E"&(RIGHT(O2,4)+1) -> E2026 | Q2: ="E"&(RIGHT(P2,4)+1) -> E2027 | R2: ="E"&(RIGHT(Q2,4)+1) -> E2028 | S2: ="E"&(RIGHT(R2,4)+1) -> E2029 | T2: ="E"&(RIGHT(S2,4)+1) -> E2030 | U2: ="E"&(RIGHT(T2,4)+1) -> E2031 | W2: E2024 | X2: E2025 | Y2: E2026 | Z2: E2027 | AA2: E2028 | AB2: E2029 | AC2: E2030 | AD2: E2031
B3: Net sales | C3: =IS!G4 -> 24006260 | D3: =IS!H4 -> 25107165 | E3: =IS!I4 -> 27144302 | F3: =IS!J4 -> 30568678 | G3: =IS!K4 -> 34193391 | H3: =IS!L4 -> 35948553 | I3: =IS!M4 -> 37899060 | J3: =IS!N4 -> 27961324 | ... O3: =IS!S4 -> 25888192 | P3: =Rev!P10 -> 27013433 | Q3: =Rev!Q10 -> 27701284 | R3: =Rev!R10 -> 28968445 | S3: =Rev!S10 -> 29683645 | T3: =Rev!T10 -> 30867609 | U3: =Rev!U10 -> 31633473 | W3: =N3/M3-1 -> 0.046322609 | X3: =O3/N3-1 -> -0.18775561 | Y3: =P3/O3-1 -> 0.043465424 | Z3: =Q3/P3-1 -> 0.025463296 | AA3: =R3/Q3-1 -> 0.045743754 | AB3: =S3/R3-1 -> 0.024688937 | AC3: =T3/S3-1 -> 0.039886075 | AD3: =U3/T3-1 -> 0.024811253
B4: Cost of sales | C4: =-IS!G5 -> -18149503 | D4: =-IS!H5 -> -17636086 | E4: =-IS!I5 -> -19586558 | F4: =-IS!J5 -> -22301143 | G4: =-IS!K5 -> -25327872 | H4: =-IS!L5 -> -27864413 | I4: =-IS!M5 -> -28348431 | J4: =-IS!N5 -> -19460229 | ... O4: =-IS!S5 -> -16587631 | P4: =-Rev!P33 -> -17682700 | Q4: =-Rev!Q33 -> -18223910 | R4: =-Rev!R33 -> -18936439 | S4: =-Rev!S33 -> -19393083 | T4: =-Rev!T33 -> -20096200 | U4: =-Rev!U33 -> -20586396
B5: Gross Profit | C5: =IS!G6 -> 5856757 | D5: =IS!H6 -> 7471080 | E5: =IS!I6 -> 7557744 | F5: =IS!J6 -> 8267535 | G5: =IS!K6 -> 8865518 | H5: =IS!L6 -> 8084139 | I5: =IS!M6 -> 9550629 | J5: =IS!N6 -> 8501095 | ... O5: =IS!S6 -> 9300561 | P5: =P3+P4 -> 9330733.5 | Q5: =Q3+Q4 -> 9477374.2 | R5: =R3+R4 -> 10032006 | S5: =S3+S4 -> 10290562 | T5: =T3+T4 -> 10771409 | U5: =U3+U4 -> 11047078
B6: Financial income | C6: =IS!G7 -> 375322 | D6: =IS!H7 -> 367210 | E6: =IS!I7 -> 418647 | F6: =IS!J7 -> 751041 | G6: =IS!K7 -> 506108 | H6: =IS!L7 -> 630350 | I6: =IS!M7 -> 889853 | J6: =IS!N7 -> 974402 | ... O6: =IS!S7 -> 1006647 | P6: ='FI&FE'!O2 -> 977523.7 | Q6: ='FI&FE'!P2 -> 927502.7 | R6: ='FI&FE'!Q2 -> 922159.3 | S6: ='FI&FE'!R2 -> 919283.02 | T6: ='FI&FE'!S2 -> 916482.27 | U6: ='FI&FE'!T2 -> 939848.61
B7: Financial expenses | C7: =-IS!G8 -> -207140 | D7: =-IS!H8 -> -89058 | E7: =-IS!I8 -> -121795 | F7: =-IS!J8 -> -68664 | G7: =-IS!K8 -> 25806 | H7: =-IS!L8 -> -74635 | I7: =-IS!M8 -> -93010 | J7: =-IS!N8 -> -105449 | ... O7: =-IS!S8 -> -26257 | P7: =-'FI&FE'!O12 -> -29677.657 | Q7: =-'FI&FE'!P12 -> -26823.982 | R7: =-'FI&FE'!Q12 -> -29623.78 | S7: =-'FI&FE'!R12 -> -32320.092 | T7: =-'FI&FE'!S12 -> -34037.104 | U7: =-'FI&FE'!T12 -> -36700.251
B8: of which: interest expenses | C8: =-IS!G9 -> -149827 | D8: =-IS!H9 -> -107216 | E8: =-IS!I9 -> -76591 | F8: =-IS!J9 -> -82182 | G8: =-IS!K9 -> -42112 | H8: =-IS!L9 -> -35245 | I8: =-IS!M9 -> -37367 | J8: =-IS!N9 -> -63681 | ... O8: =-IS!S9 -> -34346 | P8: =-'FI&FE'!O13 -> -33228.324 | Q8: =-'FI&FE'!P13 -> -34924.037 | R8: =-'FI&FE'!Q13 -> -37866.271 | S8: =-'FI&FE'!R13 -> -39228.538 | T8: =-'FI&FE'!S13 -> -41647.58 | U8: =-'FI&FE'!T13 -> -44356.65
B9: Gain/(loss) from joint ventures (from 2015) | C9: =IS!G10 -> 307216 | D9: =IS!H10 -> 343821 | E9: =IS!I10 -> 371954 | F9: =IS!J10 -> 305650 | G9: =IS!K10 -> 411874 | H9: =IS!L10 -> 354965 | I9: =IS!M10 -> 378267 | J9: =IS!N10 -> 267406 | ... O9: =IS!S10 -> 278264 | P9: =AVERAGE(N9:O9) -> 237854.5 | Q9: =AVERAGE(N9:P9) -> 237854.5 | R9: =AVERAGE(P9:Q9) -> 237854.5 | S9: =AVERAGE(Q9:R9) -> 237854.5 | T9: =AVERAGE(R9:S9) -> 237854.5 | U9: =AVERAGE(S9:T9) -> 237854.5
B10: Selling expenses | C10: =-IS!G11 -> -2132049 | D10: =-IS!H11 -> -3177311 | E10: =-IS!I11 -> -2682882 | F10: =-IS!J11 -> -2781731 | G10: =-IS!K11 -> -2811112 | H10: =-IS!L11 -> -2731091 | I10: =-IS!M11 -> -3003291 | J10: =-IS!N11 -> -2859037 | ... O10: =-IS!S11 -> -4022369 | P10: =P3*P45 -> -4052015 | Q10: =Q3*Q45 -> -3878179.8 | R10: =R3*R45 -> -3910740.1 | S10: =S3*S45 -> -4007292.1 | T10: =T3*T45 -> -4167127.2 | U10: =U3*U45 -> -4175618.5
B11: General and admin expenses | C11: =-IS!G12 -> -619075 | D11: =-IS!H12 -> -1041694 | E11: =-IS!I12 -> -1110423 | F11: =-IS!J12 -> -781829 | G11: =-IS!K12 -> -935975 | H11: =-IS!L12 -> -912705 | I11: =-IS!M12 -> -1047842 | J11: =-IS!N12 -> -702005 | ... O11: =-IS!S12 -> -983559 | P11: =P46*P3 -> -864429.86 | Q11: =Q46*Q3 -> -969544.95 | R11: =R46*R3 -> -970442.91 | S11: =S46*S3 -> -1016664.8 | T11: =T46*T3 -> -1045640.3 | U11: =U46*U3 -> -1077515.2
B12: Operating profit/(loss) | C12: =IS!G13 -> 3581029 | D12: =IS!H13 -> 3874048 | E12: =IS!I13 -> 4433244 | F12: =IS!J13 -> 5692001 | G12: =IS!K13 -> 6062219 | H12: =IS!L13 -> 5351023 | I12: =IS!M13 -> 6674606 | J12: =IS!N13 -> 6076411 | ... O12: =IS!S13 -> 5553286 | P12: =P5+P6+P7+P9+P10+P11 -> 5599989.2 | Q12: =Q5+Q6+Q7+Q9+Q10+Q11 -> 5768182.7 | R12: =R5+R6+R7+R9+R10+R11 -> 6281212.7 | S12: =S5+S6+S7+S9+S10+S11 -> 6391422.8 | T12: =T5+T6+T7+T9+T10+T11 -> 6678941.1 | U12: =U5+U6+U7+U9+U10+U11 -> 6934946.8 | W12: =N12/M12-1 -> 0.050776918 | X12: =O12/N12-1 -> -0.021785424 | Y12: =P12/O12-1 -> 0.0084100145 | Z12: =Q12/P12-1 -> 0.030034607 | AA12: =R12/Q12-1 -> 0.088941358 | AB12: =S12/R12-1 -> 0.017545991 | AC12: =T12/S12-1 -> 0.044985019 | AD12: =U12/T12-1 -> 0.038330293
B13: Other incomes | C13: =IS!G14 -> 145914 | D13: =IS!H14 -> 196849 | E13: =IS!I14 -> 132650 | F13: =IS!J14 -> 128295 | G13: =IS!K14 -> 106139 | H13: =IS!L14 -> 81738 | I13: =IS!M14 -> 74504 | J13: =IS!N14 -> 55952 | ... O13: =IS!S14 -> 152603 | P13: =AVERAGE(N13:O13) -> 90458 | Q13: =AVERAGE(N13:P13) -> 90458 | R13: =AVERAGE(P13:Q13) -> 90458 | S13: =AVERAGE(Q13:R13) -> 90458 | T13: =AVERAGE(R13:S13) -> 90458 | U13: =AVERAGE(S13:T13) -> 90458
B14: Other expenses | C14: =-IS!G15 -> -148044 | D14: =-IS!H15 -> -153339 | E14: =-IS!I15 -> -95885 | F14: =-IS!J15 -> -112898 | G14: =-IS!K15 -> -91266 | H14: =-IS!L15 -> -42322 | I14: =-IS!M15 -> -62934 | J14: =-IS!N15 -> -20545 | ... O14: =-IS!S15 -> -53924 | P14: =AVERAGE(N14:O14) -> -55920 | Q14: =AVERAGE(N14:P14) -> -55920 | R14: =AVERAGE(P14:Q14) -> -55920 | S14: =AVERAGE(Q14:R14) -> -55920 | T14: =AVERAGE(R14:S14) -> -55920 | U14: =AVERAGE(S14:T14) -> -55920
B15: Net other income/(expenses) | C15: =IS!G16 -> -2130 | D15: =IS!H16 -> 43510 | E15: =IS!I16 -> 36765 | F15: =IS!J16 -> 15397 | G15: =IS!K16 -> 14873 | H15: =IS!L16 -> 39416 | I15: =IS!M16 -> 11570 | J15: =IS!N16 -> 35407 | ... O15: =IS!S16 -> 98679 | P15: =P13+P14 -> 34538 | Q15: =Q13+Q14 -> 34538 | R15: =R13+R14 -> 34538 | S15: =S13+S14 -> 34538 | T15: =T13+T14 -> 34538 | U15: =U13+U14 -> 34538
B16: Income from investments in other entities | C16: =IS!G10 -> 307216 | D16: =IS!H10 -> 343821 | E16: =IS!I10 -> 371954 | F16: =IS!J10 -> 305650 | G16: =IS!K10 -> 411874 | H16: =IS!L10 -> 354965 | I16: =IS!M10 -> 378267 | J16: =IS!N10 -> 267406 | ... O16: =IS!S10 -> 278264 | P16: 0 | Q16: 0 | R16: 0 | S16: 0 | T16: 0 | U16: 0
B17: Net accounting profit/(loss) before tax | C17: =IS!G17 -> 3578899 | D17: =IS!H17 -> 3917558 | E17: =IS!I17 -> 4470009 | F17: =IS!J17 -> 5707398 | G17: =IS!K17 -> 6077092 | H17: =IS!L17 -> 5390440 | I17: =IS!M17 -> 6686177 | J17: =IS!N17 -> 6111818 | ... O17: =IS!S17 -> 5651966 | P17: =P12+P15+P16 -> 5634527.2 | Q17: =Q12+Q15+Q16 -> 5802720.7 | R17: =R12+R15+R16 -> 6315750.7 | S17: =S12+S15+S16 -> 6425960.8 | T17: =T12+T15+T16 -> 6713479.1 | U17: =U12+U15+U16 -> 6969484.8
B18: Corporate income tax - current | C18: =-IS!G18 -> -1057338 | D18: =-IS!H18 -> -971520 | E18: =-IS!I18 -> -1085883 | F18: =-IS!J18 -> -254203 | G18: =-IS!K18 -> -1140540 | H18: =-IS!L18 -> -1021134 | I18: =-IS!M18 -> -1347172 | J18: =-IS!N18 -> -1124943 | ... O18: =-IS!S18 -> -1057138 | P18: =(P47*P17) -> -1075512.3 | Q18: =Q47*Q17 -> -1092556.6 | R18: =R47*R17 -> -1155869.3 | S18: =S47*S17 -> -1159192.3 | T18: =T47*T17 -> -1187590.6 | U18: =U47*U17 -> -1206423.1
B19: Corporate income tax - deferred | C19: =-IS!G19 -> -26167 | D19: =-IS!H19 -> 103055 | E19: =-IS!I19 -> 215969 | F19: =-IS!J19 -> -798607 | G19: =-IS!K19 -> 12048 | H19: =-IS!L19 -> 33445 | I19: =-IS!M19 -> 31143 | J19: =-IS!N19 -> -50030 | ... O19: =-IS!S19 -> -21702 | P19: 0 | Q19: 0 | R19: 0 | S19: 0 | T19: 0 | U19: 0
B20: Corporate income tax expenses | C20: =-IS!G20 -> -1083505 | D20: =-IS!H20 -> -868465 | E20: =-IS!I20 -> -869913 | F20: =-IS!J20 -> -1052809 | G20: =-IS!K20 -> -1128492 | H20: =-IS!L20 -> -987690 | I20: =-IS!M20 -> -1316029 | J20: =-IS!N20 -> -1174972 | ... O20: =-IS!S20 -> -1078841 | P20: =P18+P19 -> -1075512.3 | Q20: =Q18+Q19 -> -1092556.6 | R20: =R18+R19 -> -1155869.3 | S20: =S18+S19 -> -1159192.3 | T20: =T18+T19 -> -1187590.6 | U20: =U18+U19 -> -1206423.1
B21: Net profit/(loss) after tax | C21: =SUM(C17,C20) -> 2495394 | D21: =SUM(D17,D20) -> 3049093 | E21: =SUM(E17,E20) -> 3600096 | F21: =SUM(F17,F20) -> 4654589 | G21: =SUM(G17,G20) -> 4948600 | H21: =SUM(H17,H20) -> 4402750 | I21: =SUM(I17,I20) -> 5370148 | J21: =SUM(J17,J20) -> 4936846 | ... U21: =SUM(U17,U20) -> 5763061.8 | W21: =N21/M21-1 -> 0.056337959 | X21: =O21/N21-1 -> 0.017431577 | Y21: =P21/O21-1 -> -0.0030854368 | Z21: =Q21/P21-1 -> 0.03315391 | AA21: =R21/Q21-1 -> 0.095478057 | AB21: =S21/R21-1 -> 0.020715038 | AC21: =T21/S21-1 -> 0.049199045 | AD21: =U21/T21-1 -> 0.042920384
B22: Minority interests | C22: =IS!G22 -> 77699 | D22: =IS!H22 -> 109116 | E22: =IS!I22 -> 189800 | F22: =IS!J22 -> 176617 | G22: =IS!K22 -> 237114 | H22: =IS!L22 -> 225318 | I22: =IS!M22 -> 316784 | J22: =IS!N22 -> 213349 | ... O22: =IS!S22 -> 149585 | P22: =P21*P48 -> 159565.52 | Q22: =Q21*Q48 -> 164855.74 | R22: =R21*R48 -> 180595.85 | S22: =S21*S48 -> 184336.9 | T22: =T21*T48 -> 193406.1 | U22: =U21*U48 -> 201707.16
B23: Attributable to parent company | C23: =IS!G23 -> 2417695 | D23: =IS!H23 -> 2939977 | E23: =IS!I23 -> 3410296 | F23: =IS!J23 -> 4477972 | G23: =IS!K23 -> 4711485 | H23: =IS!L23 -> 4177432 | I23: =IS!M23 -> 5053364 | J23: =IS!N23 -> 4723497 | ... O23: =IS!S23 -> 4423540 | P23: =P21-P22 -> 4399449.4 | Q23: =Q21-Q22 -> 4545308.3 | R23: =R21-R22 -> 4979285.5 | S23: =S21-S22 -> 5082431.6 | T23: =T21-T22 -> 5332482.4 | U23: =U21-U22 -> 5561354.6
B24: EPS_basis (VND) | C24: 3350 | D24: 3780 | E24: 4860 | F24: 6190 | G24: 6920 | H24: 6140 | I24: 7480 | J24: 7150 | K24: 5560 | L24: 7980 | M24: 3132 | N24: 3291 | O24: 3347 | P24: =P30 -> 3330.7195 | Q24: =Q30 -> 3441.1459 | R24: =R30 -> 3769.6998 | S24: =S30 -> 3847.7892 | T24: =T30 -> 4037.0968 | U24: =U30 -> 4210.3705
B25: EPS_diluted (VND) | C25: 0 | D25: 0 | E25: 0 | F25: 6190 | G25: 6920 | H25: 0 | I25: 0 | J25: 0 | K25: 0 | L25: 0 | M25: 0 | N25: 0 | O25: 0
B26: Net profit growth | D26: =D21/C21-1 -> 0.22188841 | E26: =E21/D21-1 -> 0.18071046 | F26: =F21/E21-1 -> 0.29290691 | G26: =G21/F21-1 -> 0.063165835 | H26: =H21/G21-1 -> -0.11030392 | I26: =I21/H21-1 -> 0.21972585 | J26: =J21/I21-1 -> -0.080687162 | K26: =K21/J21-1 -> -0.20408597 | ... U26: =U21/T21-1 -> 0.042920384
B27: Trích quỹ khen thưởng, phúc lợi | K27: -170371 | L27: -121347 | M27: -116231 | N27: -125583 | O27: -150126 | P27: =-Equity!P105 -> -127593.91 | Q27: =-Equity!Q105 -> -131824.15 | R27: =-Equity!R105 -> -144410.46 | S27: =-Equity!S105 -> -147401.93 | T27: =-Equity!T105 -> -154653.96 | U27: =-Equity!U105 -> -161291.77
B28: Cổ tức cổ phiếu ưu đãi
B29: Cổ phiếu lưu hành | K29: 641281186 | L29: 641281186 | M29: 1282562372 | N29: 1282562372 | O29: 1282562372 | P29: =N29 -> 1282562372 | Q29: =P29 -> 1282562372 | R29: =Q29 -> 1282562372 | S29: =R29 -> 1282562372 | T29: =S29 -> 1282562372 | U29: =T29 -> 1282562372
B30: EPS_basis (VND) | K30: =(K23+K27)*10^6/K29 -> 5468.5543 | L30: =(L23+L27)*10^6/L29 -> 7956.7343 | M30: =(M23+M27)*10^6/M29 -> 3119.828 | N30: =(N23+N27)*10^6/N29 -> 3278.2265 | O30: =(O23+O27)*10^6/O29 -> 3331.9346 | P30: =(P23+P27)*10^6/P29 -> 3330.7195 | Q30: =(Q23+Q27)*10^6/Q29 -> 3441.1459 | R30: =(R23+R27)*10^6/R29 -> 3769.6998 | ... U30: =(U23+U27)*10^6/U29 -> 4210.3705
B31: EPS_diluted (VND)
B33: SGA margin | H33: =SUM(H10:H11)/H3 -> -0.10136141 | I33: =SUM(I10:I11)/I3 -> -0.1068927 | J33: =SUM(J10:J11)/J3 -> -0.12735599 | K33: =SUM(K10:K11)/K3 -> -0.15538502 | L33: =SUM(L10:L11)/L3 -> -0.15073962 | M33: =SUM(M10:M11)/M3 -> -0.17333168 | N33: =SUM(N10:N11)/N3 -> -0.15314091 | O33: =SUM(O10:O11)/O3 -> -0.19336723 | ... U33: =SUM(U10:U11)/U3 -> -0.1660625
B35: Number of outstanding share | H35: 641281186 | I35: 641281186 | J35: 641281186 | K35: 641281186 | L35: 641281186 | M35: 1282562372 | N35: 1282562372 | O35: 1282562372 | P35: 1282562372 | Q35: 1282562372 | R35: 1282562372 | S35: 1282562372 | T35: 1282562372 | U35: 1282562372
B36: BPS | H36: =('1BS'!H101-'1BS'!H118)*10^6/'1IS'!H35 -> 23462.987 | I36: =('1BS'!I101-'1BS'!I118)*10^6/'1IS'!I35 -> 29324.52 | J36: =('1BS'!J101-'1BS'!J118)*10^6/'1IS'!J35 -> 31094.363 | K36: =('1BS'!K101-'1BS'!K118)*10^6/'1IS'!K35 -> 33092.306 | L36: =('1BS'!L101-'1BS'!L118)*10^6/'1IS'!L35 -> 36084.474 | M36: =('1BS'!M101-'1BS'!M118)*10^6/'1IS'!M35 -> 18878.078 | N36: =('1BS'!N101-'1BS'!N118)*10^6/'1IS'!N35 -> 18152.817 | O36: =('1BS'!O101-'1BS'!O118)*10^6/'1IS'!O35 -> 16492.597 | ... U36: =('1BS'!U101-'1BS'!U118)*10^6/'1IS'!U35 -> 18129.418
B38: GPM | H38: =H5/H3 -> 0.22488079 | I38: =I5/I3 -> 0.25200174 | J38: =J5/J3 -> 0.30403049 | K38: =K5/K3 -> 0.28849011 | L38: =L5/L3 -> 0.3079185 | M38: =M5/M3 -> 0.29845552 | N38: =N5/N3 -> 0.29235928 | O38: =O5/O3 -> 0.35925881 | ... U38: =U5/U3 -> 0.34922114
B39: OPM | H39: =H12/H3 -> 0.14885225 | I39: =I12/I3 -> 0.17611534 | J39: =J12/J3 -> 0.21731485 | K39: =K12/K3 -> 0.18124968 | L39: =L12/L3 -> 0.19524982 | M39: =M12/M3 -> 0.17736013 | N39: =N12/N3 -> 0.17811517 | O39: =O12/O3 -> 0.21451038 | ... U39: =U12/U3 -> 0.21922812
B40: NPM | H40: =H21/H3 -> 0.12247364 | I40: =I21/I3 -> 0.14169607 | J40: =J21/J3 -> 0.17655981 | K40: =K21/K3 -> 0.14898547 | L40: =L21/L3 -> 0.15723105 | M40: =M21/M3 -> 0.13968687 | N40: =N21/N3 -> 0.14102395 | O40: =O21/O3 -> 0.17664907 | ... U40: =U21/U3 -> 0.18218239
B42: EBIT | H42: =H17-H8 -> 5425685 | I42: =I17-I8 -> 6723544 | J42: =J17-J8 -> 6175499 | K42: =K17-K8 -> 4905634 | L42: =L17-L8 -> 6858934 | M42: =M17-M8 -> 5420625 | N42: =N17-N8 -> 5674809 | O42: =O17-O8 -> 5686312 | ... U42: =U17-U8 -> 7013841.5
B43: EBITDA | H43: =H42+'1CF'!E8 -> 6060278 | I43: =I42+'1CF'!F8 -> 7370792 | J43: =J42+'1CF'!G8 -> 6768951 | K43: =K42+'1CF'!H8 -> 5463112 | L43: =L42+'1CF'!I8 -> 7420039 | M43: =M42+'1CF'!J8 -> 5990657 | N43: =N42+'1CF'!K8 -> 6223693 | O43: =O42+'1CF'!L8 -> 6416584 | ... U43: =U42+'1CF'!R8 -> 7117298.1 | Z43: Price | AA43: =Valuation!E21 -> 55678.945
B45: Selling expense | H45: =H10/H3 -> -0.07597221 | I45: =I10/I3 -> -0.079244472 | J45: =J10/J3 -> -0.1022497 | K45: =K10/K3 -> -0.13272172 | L45: =L10/L3 -> -0.12956509 | M45: =M10/M3 -> -0.14704619 | N45: =N10/N3 -> -0.12680422 | O45: =O10/O3 -> -0.15537466 | P45: -0.15 | Q45: -0.14 | R45: -0.135 | S45: -0.135 | T45: -0.135 | U45: -0.132
...

Sheet 1CF
J2: Adjusted | T2: Adjustment | AC2: Raw
A3: Code for CF | B3: ITEMS | C3: Note | D3: 2017 | E3: =D3+1 -> 2018 | F3: =E3+1 -> 2019 | G3: =F3+1 -> 2020 | H3: =G3+1 -> 2021 | I3: =H3+1 -> 2022 | J3: =I3+1 -> 2023 | K3: =J3+1 -> 2024 | L3: =K3+1 -> 2025 | ... R3: =Q3+1 -> 2031 | T3: 2024 | U3: 2025 | V3: 2026 | W3: 2027 | X3: 2028 | Y3: 2029 | Z3: 2030 | AA3: 2031 | AC3: 2024 | AD3: 2025 | AE3: 2026 | AF3: 2027 | AG3: 2028 | AH3: 2029 | AI3: 2030 | AJ3: 2031
AM4: leave
B5: I. CASH FLOWS FROM OPERATING ACTIVITIES | AM5: leave
A6: 1 | B6: Profit/(loss) before tax | D6: =SUMIFS(CF!K:K,CF!$A:$A,'1CF'!$A$6) -> 6077092 | E6: =SUMIFS(CF!L:L,CF!$A:$A,'1CF'!$A$6) -> 5390440 | F6: =SUMIFS(CF!M:M,CF!$A:$A,'1CF'!$A$6) -> 6686177 | G6: =SUMIFS(CF!N:N,CF!$A:$A,'1CF'!$A$6) -> 6111818 | H6: =SUMIFS(CF!O:O,CF!$A:$A,'1CF'!$A$6) -> 4856894 | I6: =SUMIFS(CF!P:P,CF!$A:$A,'1CF'!$A$6) -> 6813417 | J6: =SUMIFS(CF!Q:Q,CF!$A:$A,'1CF'!$A$6) -> 5370410 | K6: =SUMIFS(CF!R:R,CF!$A:$A,'1CF'!$A$6) -> 5647359 | L6: =SUMIFS(CF!S:S,CF!$A:$A,'1CF'!$A$6) -> 5651966 | M6: =V6+AE6 -> 5634527.2 | N6: =W6+AF6 -> 5802720.7 | O6: =X6+AG6 -> 6315750.7 | P6: =Y6+AH6 -> 6425960.8 | Q6: =Z6+AI6 -> 6713479.1 | R6: =AA6+AJ6 -> 6969484.8 | AC6: ='1IS'!N17 -> 5647359 | AD6: ='1IS'!O17 -> 5651966 | AE6: ='1IS'!P17 -> 5634527.2 | AF6: ='1IS'!Q17 -> 5802720.7 | AG6: ='1IS'!R17 -> 6315750.7 | AH6: ='1IS'!S17 -> 6425960.8 | AI6: ='1IS'!T17 -> 6713479.1 | AJ6: ='1IS'!U17 -> 6969484.8 | AM6: leave
B7: Adjustments for: | AM7: leave
A8: 2 | B8: Depreciation and amortisation of fixed assets and investment properties | D8: =SUMIFS(CF!K:K,CF!$A:$A,'1CF'!$A$8) -> 625353 | E8: =SUMIFS(CF!L:L,CF!$A:$A,'1CF'!$A$8) -> 634593 | F8: =SUMIFS(CF!M:M,CF!$A:$A,'1CF'!$A$8) -> 647248 | G8: =SUMIFS(CF!N:N,CF!$A:$A,'1CF'!$A$8) -> 593452 | H8: =SUMIFS(CF!O:O,CF!$A:$A,'1CF'!$A$8) -> 557478 | I8: =SUMIFS(CF!P:P,CF!$A:$A,'1CF'!$A$8) -> 561105 | J8: =SUMIFS(CF!Q:Q,CF!$A:$A,'1CF'!$A$8) -> 570032 | K8: =SUMIFS(CF!R:R,CF!$A:$A,'1CF'!$A$8) -> 548884 | L8: =SUMIFS(CF!S:S,CF!$A:$A,'1CF'!$A$8) -> 730272 | M8: =V8+AE8 -> 800488.6 | N8: =W8+AF8 -> 812226.28 | O8: =X8+AG8 -> 799683.17 | P8: =Y8+AH8 -> 813377.07 | Q8: =Z8+AI8 -> 630981.22 | R8: =AA8+AJ8 -> 103456.63 | AC8: =-SUMIFS('1BS'!Y$3:Y$68,'1BS'!$X$3:$X$68,'1CF'!$A8)+SUMIFS('1BS'!Y$69:Y$124,'1BS'!$X$69:$X$124,'1CF'!$A8) -> 526483 | AD8: =-SUMIFS('1BS'!Z$3:Z$68,'1BS'!$X$3:$X$68,'1CF'!$A8)+SUMIFS('1BS'!Z$69:Z$124,'1BS'!$X$69:$X$124,'1CF'!$A8) -> 3550888 | AE8: =-SUMIFS('1BS'!AA$3:AA$68,'1BS'!$X$3:$X$68,'1CF'!$A8)+SUMIFS('1BS'!AA$69:AA$124,'1BS'!$X$69:$X$124,'1CF'!$A8) -> 800488.6 | AF8: =-SUMIFS('1BS'!AB$3:AB$68,'1BS'!$X$3:$X$68,'1CF'!$A8)+SUMIFS('1BS'!AB$69:AB$124,'1BS'!$X$69:$X$124,'1CF'!$A8) -> 812226.28 | AG8: =-SUMIFS('1BS'!AC$3:AC$68,'1BS'!$X$3:$X$68,'1CF'!$A8)+SUMIFS('1BS'!AC$69:AC$124,'1BS'!$X$69:$X$124,'1CF'!$A8) -> 799683.17 | AH8: =-SUMIFS('1BS'!AD$3:AD$68,'1BS'!$X$3:$X$68,'1CF'!$A8)+SUMIFS('1BS'!AD$69:AD$124,'1BS'!$X$69:$X$124,'1CF'!$A8) -> 813377.07 | AI8: =-SUMIFS('1BS'!AE$3:AE$68,'1BS'!$X$3:$X$68,'1CF'!$A8)+SUMIFS('1BS'!AE$69:AE$124,'1BS'!$X$69:$X$124,'1CF'!$A8) -> 630981.22 | AJ8: =-SUMIFS('1BS'!AF$3:AF$68,'1BS'!$X$3:$X$68,'1CF'!$A8)+SUMIFS('1BS'!AF$69:AF$124,'1BS'!$X$69:$X$124,'1CF'!$A8) -> 103456.63 | AM8: leave
A9: 3 | B9: Provisions | D9: =SUMIFS(CF!K:K,CF!$A:$A,'1CF'!$A$9) -> 81974 | E9: =SUMIFS(CF!L:L,CF!$A:$A,'1CF'!$A$9) -> 241181 | F9: =SUMIFS(CF!M:M,CF!$A:$A,'1CF'!$A$9) -> 358145 | G9: =SUMIFS(CF!N:N,CF!$A:$A,'1CF'!$A$9) -> -41309 | H9: =SUMIFS(CF!O:O,CF!$A:$A,'1CF'!$A$9) -> -63137 | I9: =SUMIFS(CF!P:P,CF!$A:$A,'1CF'!$A$9) -> -375 | J9: =SUMIFS(CF!Q:Q,CF!$A:$A,'1CF'!$A$9) -> 3418 | K9: =SUMIFS(CF!R:R,CF!$A:$A,'1CF'!$A$9) -> 4315 | L9: =SUMIFS(CF!S:S,CF!$A:$A,'1CF'!$A$9) -> 42467 | M9: =V9+AE9 -> -252929.35 | N9: =W9+AF9 -> -89715.018 | O9: =X9+AG9 -> 70440.723 | P9: =Y9+AH9 -> -13739.812 | Q9: =Z9+AI9 -> 20307.209 | R9: =AA9+AJ9 -> 9039.0122 | AC9: =-SUMIFS('1BS'!Y$3:Y$68,'1BS'!$X$3:$X$68,'1CF'!$A9)+SUMIFS('1BS'!Y$69:Y$124,'1BS'!$X$69:$X$124,'1CF'!$A9) -> -35129 | AD9: =-SUMIFS('1BS'!Z$3:Z$68,'1BS'!$X$3:$X$68,'1CF'!$A9)+SUMIFS('1BS'!Z$69:Z$124,'1BS'!$X$69:$X$124,'1CF'!$A9) -> 261007 | AE9: =-SUMIFS('1BS'!AA$3:AA$68,'1BS'!$X$3:$X$68,'1CF'!$A9)+SUMIFS('1BS'!AA$69:AA$124,'1BS'!$X$69:$X$124,'1CF'!$A9) -> -252929.35 | AF9: =-SUMIFS('1BS'!AB$3:AB$68,'1BS'!$X$3:$X$68,'1CF'!$A9)+SUMIFS('1BS'!AB$69:AB$124,'1BS'!$X$69:$X$124,'1CF'!$A9) -> -89715.018 | AG9: =-SUMIFS('1BS'!AC$3:AC$68,'1BS'!$X$3:$X$68,'1CF'!$A9)+SUMIFS('1BS'!AC$69:AC$124,'1BS'!$X$69:$X$124,'1CF'!$A9) -> 70440.723 | AH9: =-SUMIFS('1BS'!AD$3:AD$68,'1BS'!$X$3:$X$68,'1CF'!$A9)+SUMIFS('1BS'!AD$69:AD$124,'1BS'!$X$69:$X$124,'1CF'!$A9) -> -13739.812 | AI9: =-SUMIFS('1BS'!AE$3:AE$68,'1BS'!$X$3:$X$68,'1CF'!$A9)+SUMIFS('1BS'!AE$69:AE$124,'1BS'!$X$69:$X$124,'1CF'!$A9) -> 20307.209 | AJ9: =-SUMIFS('1BS'!AF$3:AF$68,'1BS'!$X$3:$X$68,'1CF'!$A9)+SUMIFS('1BS'!AF$69:AF$124,'1BS'!$X$69:$X$124,'1CF'!$A9) -> 9039.0122 | AM9: leave
A10: 4 | B10: Foreign exchange (gains)/losses arising from revaluation of monetary accounts | D10: =SUMIFS(CF!K:K,CF!$A:$A,'1CF'!$A$10) -> 106 | E10: =SUMIFS(CF!L:L,CF!$A:$A,'1CF'!$A$10) -> -72 | F10: =SUMIFS(CF!M:M,CF!$A:$A,'1CF'!$A$10) -> 790 | G10: =SUMIFS(CF!N:N,CF!$A:$A,'1CF'!$A$10) -> 10994 | H10: =SUMIFS(CF!O:O,CF!$A:$A,'1CF'!$A$10) -> -24130 | I10: =SUMIFS(CF!P:P,CF!$A:$A,'1CF'!$A$10) -> -6770 | J10: =SUMIFS(CF!Q:Q,CF!$A:$A,'1CF'!$A$10) -> 8344 | K10: =SUMIFS(CF!R:R,CF!$A:$A,'1CF'!$A$10) -> 581 | L10: =SUMIFS(CF!S:S,CF!$A:$A,'1CF'!$A$10) -> 24 | M10: =V10+AE10 -> 0 | N10: =W10+AF10 -> 0 | O10: =X10+AG10 -> 0 | P10: =Y10+AH10 -> 0 | Q10: =Z10+AI10 -> 0 | R10: =AA10+AJ10 -> 0 | AC10: =-SUMIFS('1BS'!Y$3:Y$68,'1BS'!$X$3:$X$68,'1CF'!$A10)+SUMIFS('1BS'!Y$69:Y$124,'1BS'!$X$69:$X$124,'1CF'!$A10) -> 0 | AD10: =-SUMIFS('1BS'!Z$3:Z$68,'1BS'!$X$3:$X$68,'1CF'!$A10)+SUMIFS('1BS'!Z$69:Z$124,'1BS'!$X$69:$X$124,'1CF'!$A10) -> 0 | AE10: =-SUMIFS('1BS'!AA$3:AA$68,'1BS'!$X$3:$X$68,'1CF'!$A10)+SUMIFS('1BS'!AA$69:AA$124,'1BS'!$X$69:$X$124,'1CF'!$A10) -> 0 | AF10: =-SUMIFS('1BS'!AB$3:AB$68,'1BS'!$X$3:$X$68,'1CF'!$A10)+SUMIFS('1BS'!AB$69:AB$124,'1BS'!$X$69:$X$124,'1CF'!$A10) -> 0 | AG10: =-SUMIFS('1BS'!AC$3:AC$68,'1BS'!$X$3:$X$68,'1CF'!$A10)+SUMIFS('1BS'!AC$69:AC$124,'1BS'!$X$69:$X$124,'1CF'!$A10) -> 0 | AH10: =-SUMIFS('1BS'!AD$3:AD$68,'1BS'!$X$3:$X$68,'1CF'!$A10)+SUMIFS('1BS'!AD$69:AD$124,'1BS'!$X$69:$X$124,'1CF'!$A10) -> 0 | AI10: =-SUMIFS('1BS'!AE$3:AE$68,'1BS'!$X$3:$X$68,'1CF'!$A10)+SUMIFS('1BS'!AE$69:AE$124,'1BS'!$X$69:$X$124,'1CF'!$A10) -> 0 | AJ10: =-SUMIFS('1BS'!AF$3:AF$68,'1BS'!$X$3:$X$68,'1CF'!$A10)+SUMIFS('1BS'!AF$69:AF$124,'1BS'!$X$69:$X$124,'1CF'!$A10) -> 0 | AM10: leave
A11: 5 | B11: (Profits)/losses from investing activities | D11: =SUMIFS(CF!K:K,CF!$A:$A,'1CF'!$A$11) -> -920688 | E11: =SUMIFS(CF!L:L,CF!$A:$A,'1CF'!$A$11) -> -598929 | F11: =SUMIFS(CF!M:M,CF!$A:$A,'1CF'!$A$11) -> -861838 | G11: =SUMIFS(CF!N:N,CF!$A:$A,'1CF'!$A$11) -> -1200918 | H11: =SUMIFS(CF!O:O,CF!$A:$A,'1CF'!$A$11) -> -1146221 | I11: =SUMIFS(CF!P:P,CF!$A:$A,'1CF'!$A$11) -> -1030694 | J11: =SUMIFS(CF!Q:Q,CF!$A:$A,'1CF'!$A$11) -> -1393861 | K11: =SUMIFS(CF!R:R,CF!$A:$A,'1CF'!$A$11) -> -1051087 | L11: =SUMIFS(CF!S:S,CF!$A:$A,'1CF'!$A$11) -> -1273875 | M11: =V11+AE11 -> -960583.2 | N11: =W11+AF11 -> -913313.45 | O11: =X11+AG11 -> -906594.42 | P11: =Y11+AH11 -> -904404.96 | Q11: =Z11+AI11 -> -901260.3 | R11: =AA11+AJ11 -> -924798.59 | T11: =-'FI&FE'!M3 -> -1044633 | U11: =-'FI&FE'!N3 -> -995208 | V11: =-'FI&FE'!O3 -> -960583.2 | W11: =-'FI&FE'!P3 -> -913313.45 | X11: =-'FI&FE'!Q3 -> -906594.42 | Y11: =-'FI&FE'!R3 -> -904404.96 | Z11: =-'FI&FE'!S3 -> -901260.3 | AA11: =-'FI&FE'!T3 -> -924798.59 | AC11: =-SUMIFS('1BS'!Y$3:Y$68,'1BS'!$X$3:$X$68,'1CF'!$A11)+SUMIFS('1BS'!Y$69:Y$124,'1BS'!$X$69:$X$124,'1CF'!$A11) -> 0 | AD11: =-SUMIFS('1BS'!Z$3:Z$68,'1BS'!$X$3:$X$68,'1CF'!$A11)+SUMIFS('1BS'!Z$69:Z$124,'1BS'!$X$69:$X$124,'1CF'!$A11) -> 0 | AE11: =-SUMIFS('1BS'!AA$3:AA$68,'1BS'!$X$3:$X$68,'1CF'!$A11)+SUMIFS('1BS'!AA$69:AA$124,'1BS'!$X$69:$X$124,'1CF'!$A11) -> 0 | AF11: =-SUMIFS('1BS'!AB$3:AB$68,'1BS'!$X$3:$X$68,'1CF'!$A11)+SUMIFS('1BS'!AB$69:AB$124,'1BS'!$X$69:$X$124,'1CF'!$A11) -> 0 | AG11: =-SUMIFS('1BS'!AC$3:AC$68,'1BS'!$X$3:$X$68,'1CF'!$A11)+SUMIFS('1BS'!AC$69:AC$124,'1BS'!$X$69:$X$124,'1CF'!$A11) -> 0 | AH11: =-SUMIFS('1BS'!AD$3:AD$68,'1BS'!$X$3:$X$68,'1CF'!$A11)+SUMIFS('1BS'!AD$69:AD$124,'1BS'!$X$69:$X$124,'1CF'!$A11) -> 0 | AI11: =-SUMIFS('1BS'!AE$3:AE$68,'1BS'!$X$3:$X$68,'1CF'!$A11)+SUMIFS('1BS'!AE$69:AE$124,'1BS'!$X$69:$X$124,'1CF'!$A11) -> 0 | AJ11: =-SUMIFS('1BS'!AF$3:AF$68,'1BS'!$X$3:$X$68,'1CF'!$A11)+SUMIFS('1BS'!AF$69:AF$124,'1BS'!$X$69:$X$124,'1CF'!$A11) -> 0 | AK11: Loại lãi tiền gửi/thanh lý TSCĐ | AM11: leave
A12: 6 | B12: Interest expense | D12: =SUMIFS(CF!K:K,CF!$A:$A,'1CF'!$A$12) -> 42112 | E12: =SUMIFS(CF!L:L,CF!$A:$A,'1CF'!$A$12) -> 35245 | F12: =SUMIFS(CF!M:M,CF!$A:$A,'1CF'!$A$12) -> 37367 | G12: =SUMIFS(CF!N:N,CF!$A:$A,'1CF'!$A$12) -> 63681 | H12: =SUMIFS(CF!O:O,CF!$A:$A,'1CF'!$A$12) -> 48740 | I12: =SUMIFS(CF!P:P,CF!$A:$A,'1CF'!$A$12) -> 45517 | J12: =SUMIFS(CF!Q:Q,CF!$A:$A,'1CF'!$A$12) -> 50215 | K12: =SUMIFS(CF!R:R,CF!$A:$A,'1CF'!$A$12) -> 27450 | L12: =SUMIFS(CF!S:S,CF!$A:$A,'1CF'!$A$12) -> 34346 | M12: =V12+AE12 -> 33228.324 | N12: =W12+AF12 -> 34924.037 | O12: =X12+AG12 -> 37866.271 | P12: =Y12+AH12 -> 39228.538 | Q12: =Z12+AI12 -> 41647.58 | R12: =AA12+AJ12 -> 44356.65 | T12: ='FI&FE'!M13 -> 27449 | U12: ='FI&FE'!N13 -> 34346 | V12: ='FI&FE'!O13 -> 33228.324 | W12: ='FI&FE'!P13 -> 34924.037 | X12: ='FI&FE'!Q13 -> 37866.271 | Y12: ='FI&FE'!R13 -> 39228.538 | Z12: ='FI&FE'!S13 -> 41647.58 | AA12: ='FI&FE'!T13 -> 44356.65 | AC12: =-SUMIFS('1BS'!Y$3:Y$68,'1BS'!$X$3:$X$68,'1CF'!$A12)+SUMIFS('1BS'!Y$69:Y$124,'1BS'!$X$69:$X$124,'1CF'!$A12) -> 0 | AD12: =-SUMIFS('1BS'!Z$3:Z$68,'1BS'!$X$3:$X$68,'1CF'!$A12)+SUMIFS('1BS'!Z$69:Z$124,'1BS'!$X$69:$X$124,'1CF'!$A12) -> 0 | AE12: =-SUMIFS('1BS'!AA$3:AA$68,'1BS'!$X$3:$X$68,'1CF'!$A12)+SUMIFS('1BS'!AA$69:AA$124,'1BS'!$X$69:$X$124,'1CF'!$A12) -> 0 | AF12: =-SUMIFS('1BS'!AB$3:AB$68,'1BS'!$X$3:$X$68,'1CF'!$A12)+SUMIFS('1BS'!AB$69:AB$124,'1BS'!$X$69:$X$124,'1CF'!$A12) -> 0 | AG12: =-SUMIFS('1BS'!AC$3:AC$68,'1BS'!$X$3:$X$68,'1CF'!$A12)+SUMIFS('1BS'!AC$69:AC$124,'1BS'!$X$69:$X$124,'1CF'!$A12) -> 0 | AH12: =-SUMIFS('1BS'!AD$3:AD$68,'1BS'!$X$3:$X$68,'1CF'!$A12)+SUMIFS('1BS'!AD$69:AD$124,'1BS'!$X$69:$X$124,'1CF'!$A12) -> 0 | AI12: =-SUMIFS('1BS'!AE$3:AE$68,'1BS'!$X$3:$X$68,'1CF'!$A12)+SUMIFS('1BS'!AE$69:AE$124,'1BS'!$X$69:$X$124,'1CF'!$A12) -> 0 | AJ12: =-SUMIFS('1BS'!AF$3:AF$68,'1BS'!$X$3:$X$68,'1CF'!$A12)+SUMIFS('1BS'!AF$69:AF$124,'1BS'!$X$69:$X$124,'1CF'!$A12) -> 0 | AK12: Cộng lại int exp | AM12: leave
A13: 7 | B13: Other adjustments | D13: =SUMIFS(CF!K:K,CF!$A:$A,'1CF'!$A$13) -> 0 | E13: =SUMIFS(CF!L:L,CF!$A:$A,'1CF'!$A$13) -> 0 | F13: =SUMIFS(CF!M:M,CF!$A:$A,'1CF'!$A$13) -> 0 | G13: =SUMIFS(CF!N:N,CF!$A:$A,'1CF'!$A$13) -> 0 | H13: =SUMIFS(CF!O:O,CF!$A:$A,'1CF'!$A$13) -> 0 | I13: =SUMIFS(CF!P:P,CF!$A:$A,'1CF'!$A$13) -> 0 | J13: =SUMIFS(CF!Q:Q,CF!$A:$A,'1CF'!$A$13) -> 0 | K13: =SUMIFS(CF!R:R,CF!$A:$A,'1CF'!$A$13) -> 0 | L13: =SUMIFS(CF!S:S,CF!$A:$A,'1CF'!$A$13) -> 0 | M13: =SUMIFS(CF!T:T,CF!$A:$A,'1CF'!$A$13) -> 0 | N13: =SUMIFS(CF!U:U,CF!$A:$A,'1CF'!$A$13) -> 0 | O13: =SUMIFS(CF!V:V,CF!$A:$A,'1CF'!$A$13) -> 0 | P13: =SUMIFS(CF!W:W,CF!$A:$A,'1CF'!$A$13) -> 0 | Q13: =SUMIFS(CF!X:X,CF!$A:$A,'1CF'!$A$13) -> 0 | R13: =SUMIFS(CF!Y:Y,CF!$A:$A,'1CF'!$A$13) -> 0 | AC13: =-SUMIFS('1BS'!Y$3:Y$68,'1BS'!$X$3:$X$68,'1CF'!$A13)+SUMIFS('1BS'!Y$69:Y$124,'1BS'!$X$69:$X$124,'1CF'!$A13) -> 0 | AD13: =-SUMIFS('1BS'!Z$3:Z$68,'1BS'!$X$3:$X$68,'1CF'!$A13)+SUMIFS('1BS'!Z$69:Z$124,'1BS'!$X$69:$X$124,'1CF'!$A13) -> 0 | AE13: =-SUMIFS('1BS'!AA$3:AA$68,'1BS'!$X$3:$X$68,'1CF'!$A13)+SUMIFS('1BS'!AA$69:AA$124,'1BS'!$X$69:$X$124,'1CF'!$A13) -> 0 | AF13: =-SUMIFS('1BS'!AB$3:AB$68,'1BS'!$X$3:$X$68,'1CF'!$A13)+SUMIFS('1BS'!AB$69:AB$124,'1BS'!$X$69:$X$124,'1CF'!$A13) -> 0 | AG13: =-SUMIFS('1BS'!AC$3:AC$68,'1BS'!$X$3:$X$68,'1CF'!$A13)+SUMIFS('1BS'!AC$69:AC$124,'1BS'!$X$69:$X$124,'1CF'!$A13) -> 0 | AH13: =-SUMIFS('1BS'!AD$3:AD$68,'1BS'!$X$3:$X$68,'1CF'!$A13)+SUMIFS('1BS'!AD$69:AD$124,'1BS'!$X$69:$X$124,'1CF'!$A13) -> 0 | AI13: =-SUMIFS('1BS'!AE$3:AE$68,'1BS'!$X$3:$X$68,'1CF'!$A13)+SUMIFS('1BS'!AE$69:AE$124,'1BS'!$X$69:$X$124,'1CF'!$A13) -> 0 | AJ13: =-SUMIFS('1BS'!AF$3:AF$68,'1BS'!$X$3:$X$68,'1CF'!$A13)+SUMIFS('1BS'!AF$69:AF$124,'1BS'!$X$69:$X$124,'1CF'!$A13) -> 0 | AM13: leave
AM14: leave
A15: 8 | B15: Operating profit/(loss) before changes in working capital | D15: =SUMIFS(CF!K:K,CF!$A:$A,'1CF'!$A$15) -> 5905949 | E15: =SUMIFS(CF!L:L,CF!$A:$A,'1CF'!$A$15) -> 5347492 | F15: =SUMIFS(CF!M:M,CF!$A:$A,'1CF'!$A$15) -> 6489622 | G15: =SUMIFS(CF!N:N,CF!$A:$A,'1CF'!$A$15) -> 5537718 | H15: =SUMIFS(CF!O:O,CF!$A:$A,'1CF'!$A$15) -> 4056683 | I15: =SUMIFS(CF!P:P,CF!$A:$A,'1CF'!$A$15) -> 6059081 | J15: =SUMIFS(CF!Q:Q,CF!$A:$A,'1CF'!$A$15) -> 4376504 | K15: =SUMIFS(CF!R:R,CF!$A:$A,'1CF'!$A$15) -> 4980056 | L15: =SUMIFS(CF!S:S,CF!$A:$A,'1CF'!$A$15) -> 5185201 | M15: =SUM(M8:M13,M6) -> 5254731.6 | N15: =SUM(N8:N13,N6) -> 5646842.5 | O15: =SUM(O8:O13,O6) -> 6317146.4 | P15: =SUM(P8:P13,P6) -> 6360421.6 | Q15: =SUM(Q8:Q13,Q6) -> 6505154.8 | R15: =SUM(R8:R13,R6) -> 6201538.5 | AC15: =SUM(AC8:AC13,AC6) -> 6138713 | AD15: =SUM(AD8:AD13,AD6) -> 9463861 | AE15: =SUM(AE8:AE13,AE6) -> 6182086.5 | AF15: =SUM(AF8:AF13,AF6) -> 6525232 | AG15: =SUM(AG8:AG13,AG6) -> 7185874.6 | AH15: =SUM(AH8:AH13,AH6) -> 7225598.1 | AI15: =SUM(AI8:AI13,AI6) -> 7364767.5 | AJ15: =SUM(AJ8:AJ13,AJ6) -> 7081980.5 | AM15: leave
A16: 9 | B16: (Increase)/decrease in receivables | D16: =SUMIFS(CF!K:K,CF!$A:$A,'1CF'!$A$16) -> 187691 | E16: =SUMIFS(CF!L:L,CF!$A:$A,'1CF'!$A$16) -> 119831 | F16: =SUMIFS(CF!M:M,CF!$A:$A,'1CF'!$A$16) -> 95622 | G16: =SUMIFS(CF!N:N,CF!$A:$A,'1CF'!$A$16) -> 70186 | H16: =SUMIFS(CF!O:O,CF!$A:$A,'1CF'!$A$16) -> -52722 | I16: =SUMIFS(CF!P:P,CF!$A:$A,'1CF'!$A$16) -> -318889 | J16: =SUMIFS(CF!Q:Q,CF!$A:$A,'1CF'!$A$16) -> -39584 | K16: =SUMIFS(CF!R:R,CF!$A:$A,'1CF'!$A$16) -> 13722 | L16: =SUMIFS(CF!S:S,CF!$A:$A,'1CF'!$A$16) -> -92591 | M16: =V16+AE16 -> 100691.16 | N16: =W16+AF16 -> 117698.3 | O16: =X16+AG16 -> -143015.51 | P16: =Y16+AH16 -> -26304.982 | Q16: =Z16+AI16 -> -41929.736 | R16: =AA16+AJ16 -> -51425.983 | AC16: =-SUMIFS('1BS'!Y$3:Y$68,'1BS'!$X$3:$X$68,'1CF'!$A16)+SUMIFS('1BS'!Y$69:Y$124,'1BS'!$X$69:$X$124,'1CF'!$A16) -> -629075 | AD16: =-SUMIFS('1BS'!Z$3:Z$68,'1BS'!$X$3:$X$68,'1CF'!$A16)+SUMIFS('1BS'!Z$69:Z$124,'1BS'!$X$69:$X$124,'1CF'!$A16) -> 662768 | AE16: =-SUMIFS('1BS'!AA$3:AA$68,'1BS'!$X$3:$X$68,'1CF'!$A16)+SUMIFS('1BS'!AA$69:AA$124,'1BS'!$X$69:$X$124,'1CF'!$A16) -> 100691.16 | AF16: =-SUMIFS('1BS'!AB$3:AB$68,'1BS'!$X$3:$X$68,'1CF'!$A16)+SUMIFS('1BS'!AB$69:AB$124,'1BS'!$X$69:$X$124,'1CF'!$A16) -> 117698.3 | AG16: =-SUMIFS('1BS'!AC$3:AC$68,'1BS'!$X$3:$X$68,'1CF'!$A16)+SUMIFS('1BS'!AC$69:AC$124,'1BS'!$X$69:$X$124,'1CF'!$A16) -> -143015.51 | AH16: =-SUMIFS('1BS'!AD$3:AD$68,'1BS'!$X$3:$X$68,'1CF'!$A16)+SUMIFS('1BS'!AD$69:AD$124,'1BS'!$X$69:$X$124,'1CF'!$A16) -> -26304.982 | AI16: =-SUMIFS('1BS'!AE$3:AE$68,'1BS'!$X$3:$X$68,'1CF'!$A16)+SUMIFS('1BS'!AE$69:AE$124,'1BS'!$X$69:$X$124,'1CF'!$A16) -> -41929.736 | AJ16: =-SUMIFS('1BS'!AF$3:AF$68,'1BS'!$X$3:$X$68,'1CF'!$A16)+SUMIFS('1BS'!AF$69:AF$124,'1BS'!$X$69:$X$124,'1CF'!$A16) -> -51425.983 | AM16: leave
